{"type":"l2update","product_id":"BTC-USD","changes":[["buy","58695.04","0.00000000"]],"time":"2021-04-02T01:29:51.329865Z"}
{"type":"l2update","product_id":"BTC-USD","changes":[["buy","58803.16","0.00000000"]],"time":"2021-04-02T01:29:51.329889Z"}
{"type":"l2update","product_id":"BTC-USD","changes":[["buy","58570.64","0.01000000"]],"time":"2021-04-02T01:29:51.330075Z"}
{"type":"l2update","product_id":"BTC-USD","changes":[["buy","58673.76","0.03567375"]],"time":"2021-04-02T01:29:51.330261Z"}
{"type":"l2update","product_id":"BTC-USD","changes":[["sell","58833.69","0.00000000"]],"time":"2021-04-02T01:29:51.333621Z"}
{"type":"l2update","product_id":"BTC-USD","changes":[["sell","59477.29","0.01000000"]],"time":"2021-04-02T01:29:51.337682Z"}
{"type":"l2update","product_id":"BTC-USD","changes":[["buy","58714.14","0.00851583"]],"time":"2021-04-02T01:29:51.345242Z"}
{"type":"l2update","product_id":"BTC-USD","changes":[["sell","58831.40","0.15763862"]],"time":"2021-04-02T01:29:51.345582Z"}
{"type":"l2update","product_id":"BTC-USD","changes":[["buy","58803.29","0.00000000"]],"time":"2021-04-02T01:29:51.371698Z"}
{"type":"l2update","product_id":"BTC-USD","changes":[["buy","58595.25","0.00000000"]],"time":"2021-04-02T01:29:51.372482Z"}
{"type":"l2update","product_id":"BTC-USD","changes":[["sell","58844.91","0.00000000"]],"time":"2021-04-02T01:29:51.375976Z"}
{"type":"l2update","product_id":"BTC-USD","changes":[["buy","58613.34","0.01000000"]],"time":"2021-04-02T01:29:51.384087Z"}
{"type":"l2update","product_id":"BTC-USD","changes":[["sell","58910.14","0.00000000"]],"time":"2021-04-02T01:29:51.384504Z"}
{"type":"l2update","product_id":"BTC-USD","changes":[["buy","58750.09","0.00000000"]],"time":"2021-04-02T01:29:51.417600Z"}
{"type":"l2update","product_id":"BTC-USD","changes":[["sell","58833.68","0.00000000"]],"time":"2021-04-02T01:29:51.419083Z"}
{"type":"l2update","product_id":"BTC-USD","changes":[["sell","58831.39","0.03296694"]],"time":"2021-04-02T01:29:51.425754Z"}
{"type":"l2update","product_id":"BTC-USD","changes":[["sell","59477.29","0.00000000"]],"time":"2021-04-02T01:29:51.435465Z"}
{"type":"l2update","product_id":"BTC-USD","changes":[["sell","59455.75","0.01000000"]],"time":"2021-04-02T01:29:51.445274Z"}
{"type":"l2update","product_id":"BTC-USD","changes":[["buy","58802.89","0.40350000"]],"time":"2021-04-02T01:29:51.464951Z"}
{"type":"l2update","product_id":"BTC-USD","changes":[["sell","58844.90","0.40460000"]],"time":"2021-04-02T01:29:51.476360Z"}
{"type":"l2update","product_id":"BTC-USD","changes":[["buy","58800.01","0.05000000"]],"time":"2021-04-02T01:29:51.476429Z"}
{"type":"l2update","product_id":"BTC-USD","changes":[["buy","58750.09","0.60415044"]],"time":"2021-04-02T01:29:51.503842Z"}
{"type":"l2update","product_id":"BTC-USD","changes":[["buy","58828.40","0.01072212"]],"time":"2021-04-02T01:29:51.515944Z"}
{"type":"l2update","product_id":"BTC-USD","changes":[["sell","58831.39","0.00000000"]],"time":"2021-04-02T01:29:51.521960Z"}
{"type":"l2update","product_id":"BTC-USD","changes":[["sell","58831.39","0.05832612"]],"time":"2021-04-02T01:29:51.527411Z"}
{"type":"l2update","product_id":"BTC-USD","changes":[["buy","58828.40","0.00000000"]],"time":"2021-04-02T01:29:51.529882Z"}
{"type":"l2update","product_id":"BTC-USD","changes":[["sell","58831.39","0.00000000"]],"time":"2021-04-02T01:29:51.534705Z"}
{"type":"l2update","product_id":"BTC-USD","changes":[["sell","58831.39","0.03296694"]],"time":"2021-04-02T01:29:51.543254Z"}
{"type":"l2update","product_id":"BTC-USD","changes":[["sell","58872.52","0.00000000"]],"time":"2021-04-02T01:29:51.547265Z"}
{"type":"l2update","product_id":"BTC-USD","changes":[["sell","58836.32","0.00000000"]],"time":"2021-04-02T01:29:51.553888Z"}
{"type":"l2update","product_id":"BTC-USD","changes":[["sell","58872.56","0.70703985"]],"time":"2021-04-02T01:29:51.565786Z"}
{"type":"l2update","product_id":"BTC-USD","changes":[["sell","58831.39","0.00000000"]],"time":"2021-04-02T01:29:51.566384Z"}
{"type":"l2update","product_id":"BTC-USD","changes":[["sell","58835.45","0.08498278"]],"time":"2021-04-02T01:29:51.570344Z"}
{"type":"l2update","product_id":"BTC-USD","changes":[["sell","58831.39","0.05832612"]],"time":"2021-04-02T01:29:51.573535Z"}
{"type":"l2update","product_id":"BTC-USD","changes":[["buy","58800.01","0.00000000"]],"time":"2021-04-02T01:29:51.578060Z"}
{"type":"l2update","product_id":"BTC-USD","changes":[["sell","58831.39","0.00000000"]],"time":"2021-04-02T01:29:51.581938Z"}
{"type":"l2update","product_id":"BTC-USD","changes":[["sell","58831.39","0.03296694"]],"time":"2021-04-02T01:29:51.589055Z"}
{"type":"l2update","product_id":"BTC-USD","changes":[["sell","58831.39","0.00000000"]],"time":"2021-04-02T01:29:51.594195Z"}
{"type":"l2update","product_id":"BTC-USD","changes":[["sell","58835.45","0.00000000"]],"time":"2021-04-02T01:29:51.597175Z"}
{"type":"l2update","product_id":"BTC-USD","changes":[["sell","58831.39","0.05832612"]],"time":"2021-04-02T01:29:51.597195Z"}
{"type":"l2update","product_id":"BTC-USD","changes":[["buy","58828.40","0.00459098"]],"time":"2021-04-02T01:29:51.600885Z"}
{"type":"l2update","product_id":"BTC-USD","changes":[["sell","58831.39","0.00000000"]],"time":"2021-04-02T01:29:51.602407Z"}
{"type":"l2update","product_id":"BTC-USD","changes":[["sell","58836.32","0.08498152"]],"time":"2021-04-02T01:29:51.611543Z"}
{"type":"l2update","product_id":"BTC-USD","changes":[["sell","58831.39","0.03296694"]],"time":"2021-04-02T01:29:51.611710Z"}
{"type":"l2update","product_id":"BTC-USD","changes":[["buy","58827.73","0.02941327"]],"time":"2021-04-02T01:29:51.615457Z"}
{"type":"l2update","product_id":"BTC-USD","changes":[["sell","58831.39","0.00000000"]],"time":"2021-04-02T01:29:51.623205Z"}
{"type":"l2update","product_id":"BTC-USD","changes":[["sell","58872.56","0.00000000"]],"time":"2021-04-02T01:29:51.627103Z"}
{"type":"l2update","product_id":"BTC-USD","changes":[["sell","58831.39","0.05832612"]],"time":"2021-04-02T01:29:51.627177Z"}
{"type":"l2update","product_id":"BTC-USD","changes":[["sell","58839.11","0.02786921"]],"time":"2021-04-02T01:29:51.627357Z"}
{"type":"l2update","product_id":"BTC-USD","changes":[["sell","58831.39","0.00000000"]],"time":"2021-04-02T01:29:51.631466Z"}
{"type":"l2update","product_id":"BTC-USD","changes":[["sell","58831.39","0.03296694"]],"time":"2021-04-02T01:29:51.639208Z"}
{"type":"l2update","product_id":"BTC-USD","changes":[["sell","59455.75","0.00000000"]],"time":"2021-04-02T01:29:51.639786Z"}
{"type":"l2update","product_id":"BTC-USD","changes":[["sell","58831.39","0.00000000"]],"time":"2021-04-02T01:29:51.643469Z"}
{"type":"l2update","product_id":"BTC-USD","changes":[["sell","58872.55","0.70703985"]],"time":"2021-04-02T01:29:51.643490Z"}
{"type":"l2update","product_id":"BTC-USD","changes":[["sell","58831.39","0.05832612"]],"time":"2021-04-02T01:29:51.647279Z"}
{"type":"l2update","product_id":"BTC-USD","changes":[["sell","59477.29","0.08406570"]],"time":"2021-04-02T01:29:51.647370Z"}
{"type":"l2update","product_id":"BTC-USD","changes":[["buy","58761.45","0.33120000"]],"time":"2021-04-02T01:29:51.647412Z"}
{"type":"l2update","product_id":"BTC-USD","changes":[["buy","58803.16","0.04000000"]],"time":"2021-04-02T01:29:51.647464Z"}
{"type":"l2update","product_id":"BTC-USD","changes":[["buy","58802.06","0.00000000"]],"time":"2021-04-02T01:29:51.651487Z"}
{"type":"l2update","product_id":"BTC-USD","changes":[["buy","58828.40","0.00222777"]],"time":"2021-04-02T01:29:51.665322Z"}
{"type":"l2update","product_id":"BTC-USD","changes":[["sell","58831.39","0.00000000"]],"time":"2021-04-02T01:29:51.669393Z"}
{"type":"l2update","product_id":"BTC-USD","changes":[["buy","58827.73","0.00000000"]],"time":"2021-04-02T01:29:51.671925Z"}
{"type":"l2update","product_id":"BTC-USD","changes":[["sell","58831.39","0.03296694"]],"time":"2021-04-02T01:29:51.673261Z"}
{"type":"l2update","product_id":"BTC-USD","changes":[["sell","58831.39","0.09129306"]],"time":"2021-04-02T01:29:51.680795Z"}
{"type":"l2update","product_id":"BTC-USD","changes":[["buy","58828.40","0.00000000"]],"time":"2021-04-02T01:29:51.684370Z"}
{"type":"l2update","product_id":"BTC-USD","changes":[["sell","58831.39","0.05832612"]],"time":"2021-04-02T01:29:51.684791Z"}
{"type":"l2update","product_id":"BTC-USD","changes":[["sell","58831.39","0.00000000"]],"time":"2021-04-02T01:29:51.688545Z"}
{"type":"l2update","product_id":"BTC-USD","changes":[["buy","58750.09","0.00000000"]],"time":"2021-04-02T01:29:51.689463Z"}
{"type":"l2update","product_id":"BTC-USD","changes":[["buy","58827.72","0.57395699"]],"time":"2021-04-02T01:29:51.704846Z"}
{"type":"l2update","product_id":"BTC-USD","changes":[["sell","58872.55","0.00000000"]],"time":"2021-04-02T01:29:51.707193Z"}
{"type":"l2update","product_id":"BTC-USD","changes":[["sell","58831.39","0.09129306"]],"time":"2021-04-02T01:29:51.711794Z"}
{"type":"l2update","product_id":"BTC-USD","changes":[["sell","58831.39","0.00000000"]],"time":"2021-04-02T01:29:51.716928Z"}
{"type":"l2update","product_id":"BTC-USD","changes":[["sell","58872.54","0.70703985"]],"time":"2021-04-02T01:29:51.723006Z"}
{"type":"l2update","product_id":"BTC-USD","changes":[["sell","58829.59","0.34007906"]],"time":"2021-04-02T01:29:51.734786Z"}
{"type":"l2update","product_id":"BTC-USD","changes":[["buy","58827.72","0.57159361"]],"time":"2021-04-02T01:29:51.734828Z"}
{"type":"l2update","product_id":"BTC-USD","changes":[["sell","58829.58","0.09129306"]],"time":"2021-04-02T01:29:51.746570Z"}
{"type":"l2update","product_id":"BTC-USD","changes":[["buy","58817.00","0.34007906"]],"time":"2021-04-02T01:29:51.746643Z"}
{"type":"l2update","product_id":"BTC-USD","changes":[["buy","58470.84","0.00000000"]],"time":"2021-04-02T01:29:51.748921Z"}
{"type":"l2update","product_id":"BTC-USD","changes":[["buy","58827.72","0.56923024"]],"time":"2021-04-02T01:29:51.754348Z"}
{"type":"l2update","product_id":"BTC-USD","changes":[["sell","58829.58","0.00000000"]],"time":"2021-04-02T01:29:51.754861Z"}
{"type":"l2update","product_id":"BTC-USD","changes":[["buy","58491.47","0.04840000"]],"time":"2021-04-02T01:29:51.757440Z"}
{"type":"l2update","product_id":"BTC-USD","changes":[["sell","58829.58","0.09129306"]],"time":"2021-04-02T01:29:51.765918Z"}
{"type":"l2update","product_id":"BTC-USD","changes":[["buy","58827.72","0.56686686"]],"time":"2021-04-02T01:29:51.765956Z"}
{"type":"l2update","product_id":"BTC-USD","changes":[["sell","58829.58","0.00000000"]],"time":"2021-04-02T01:29:51.770535Z"}
{"type":"l2update","product_id":"BTC-USD","changes":[["buy","58750.09","1.00000000"]],"time":"2021-04-02T01:29:51.771392Z"}
{"type":"l2update","product_id":"BTC-USD","changes":[["sell","58829.58","0.09129306"]],"time":"2021-04-02T01:29:51.784219Z"}
{"type":"l2update","product_id":"BTC-USD","changes":[["buy","58769.35","0.00000000"]],"time":"2021-04-02T01:29:51.801988Z"}
{"type":"l2update","product_id":"BTC-USD","changes":[["buy","58820.82","0.00000000"]],"time":"2021-04-02T01:29:51.834393Z"}
{"type":"l2update","product_id":"BTC-USD","changes":[["buy","58828.40","0.01279000"]],"time":"2021-04-02T01:29:51.837088Z"}
{"type":"l2update","product_id":"BTC-USD","changes":[["sell","58999.02","0.00000000"]],"time":"2021-04-02T01:29:51.842630Z"}
{"type":"l2update","product_id":"BTC-USD","changes":[["sell","58829.58","0.00000000"]],"time":"2021-04-02T01:29:51.843155Z"}
{"type":"l2update","product_id":"BTC-USD","changes":[["buy","58821.79","0.24995469"]],"time":"2021-04-02T01:29:51.844665Z"}
{"type":"l2update","product_id":"BTC-USD","changes":[["buy","58802.89","0.00000000"]],"time":"2021-04-02T01:29:51.847349Z"}
{"type":"l2update","product_id":"BTC-USD","changes":[["sell","58828.41","0.26064629"]],"time":"2021-04-02T01:29:51.848652Z"}
{"type":"l2update","product_id":"BTC-USD","changes":[["sell","58844.90","0.00000000"]],"time":"2021-04-02T01:29:51.850365Z"}
{"type":"l2update","product_id":"BTC-USD","changes":[["sell","58980.29","0.01000000"]],"time":"2021-04-02T01:29:51.852505Z"}
{"type":"l2update","product_id":"BTC-USD","changes":[["sell","58828.41","0.22767935"]],"time":"2021-04-02T01:29:51.864728Z"}
{"type":"l2update","product_id":"BTC-USD","changes":[["sell","58872.54","0.00000000"]],"time":"2021-04-02T01:29:51.866611Z"}
{"type":"l2update","product_id":"BTC-USD","changes":[["buy","58659.11","0.01000000"]],"time":"2021-04-02T01:29:51.866702Z"}
{"type":"l2update","product_id":"BTC-USD","changes":[["sell","58828.41","0.28600547"]],"time":"2021-04-02T01:29:51.870574Z"}
{"type":"l2update","product_id":"BTC-USD","changes":[["buy","58570.64","0.00000000"]],"time":"2021-04-02T01:29:51.873120Z"}
{"type":"l2update","product_id":"BTC-USD","changes":[["buy","58491.47","0.00000000"]],"time":"2021-04-02T01:29:51.876257Z"}
{"type":"l2update","product_id":"BTC-USD","changes":[["sell","58872.56","0.70703985"]],"time":"2021-04-02T01:29:51.881243Z"}
{"type":"l2update","product_id":"BTC-USD","changes":[["buy","58613.12","0.01000000"]],"time":"2021-04-02T01:29:51.881922Z"}
{"type":"l2update","product_id":"BTC-USD","changes":[["buy","58512.09","0.04840000"]],"time":"2021-04-02T01:29:51.885026Z"}
{"type":"l2update","product_id":"BTC-USD","changes":[["buy","58673.76","0.00000000"]],"time":"2021-04-02T01:29:51.893845Z"}
{"type":"l2update","product_id":"BTC-USD","changes":[["buy","58613.12","0.00000000"]],"time":"2021-04-02T01:29:51.898298Z"}
{"type":"l2update","product_id":"BTC-USD","changes":[["sell","59477.29","0.00000000"]],"time":"2021-04-02T01:29:51.900519Z"}
{"type":"l2update","product_id":"BTC-USD","changes":[["buy","58692.54","0.01000000"]],"time":"2021-04-02T01:29:51.903893Z"}
{"type":"l2update","product_id":"BTC-USD","changes":[["buy","58591.88","0.08516400"]],"time":"2021-04-02T01:29:51.911385Z"}
{"type":"l2update","product_id":"BTC-USD","changes":[["sell","58970.64","0.00000000"]],"time":"2021-04-02T01:29:51.922374Z"}
{"type":"l2update","product_id":"BTC-USD","changes":[["sell","59498.83","0.08403527"]],"time":"2021-04-02T01:29:51.923419Z"}
{"type":"l2update","product_id":"BTC-USD","changes":[["sell","59003.17","0.00000000"]],"time":"2021-04-02T01:29:51.924873Z"}
{"type":"l2update","product_id":"BTC-USD","changes":[["sell","59022.32","0.01000000"]],"time":"2021-04-02T01:29:51.930509Z"}
{"type":"l2update","product_id":"BTC-USD","changes":[["sell","58872.56","0.00000000"]],"time":"2021-04-02T01:29:51.930788Z"}
{"type":"l2update","product_id":"BTC-USD","changes":[["buy","58680.86","0.00000000"]],"time":"2021-04-02T01:29:51.933058Z"}
{"type":"l2update","product_id":"BTC-USD","changes":[["sell","59024.42","0.01485000"]],"time":"2021-04-02T01:29:51.934322Z"}
{"type":"l2update","product_id":"BTC-USD","changes":[["buy","58802.24","0.41560000"]],"time":"2021-04-02T01:29:51.938345Z"}
{"type":"l2update","product_id":"BTC-USD","changes":[["buy","58698.93","0.02147699"]],"time":"2021-04-02T01:29:51.942612Z"}
{"type":"l2update","product_id":"BTC-USD","changes":[["sell","58845.43","0.41410000"]],"time":"2021-04-02T01:29:51.945912Z"}
{"type":"l2update","product_id":"BTC-USD","changes":[["sell","58872.55","0.70703985"]],"time":"2021-04-02T01:29:51.946148Z"}
{"type":"l2update","product_id":"BTC-USD","changes":[["sell","58971.09","0.00000000"]],"time":"2021-04-02T01:29:51.948722Z"}
{"type":"l2update","product_id":"BTC-USD","changes":[["sell","58990.31","0.01500800"]],"time":"2021-04-02T01:29:51.964887Z"}
{"type":"l2update","product_id":"BTC-USD","changes":[["sell","58828.41","0.22767935"]],"time":"2021-04-02T01:29:51.966614Z"}
{"type":"l2update","product_id":"BTC-USD","changes":[["sell","58828.41","0.26064629"]],"time":"2021-04-02T01:29:51.976587Z"}
{"type":"l2update","product_id":"BTC-USD","changes":[["buy","58591.88","0.00000000"]],"time":"2021-04-02T01:29:51.977784Z"}
{"type":"l2update","product_id":"BTC-USD","changes":[["sell","59498.83","0.00000000"]],"time":"2021-04-02T01:29:51.982096Z"}
{"type":"l2update","product_id":"BTC-USD","changes":[["buy","58623.74","0.08528967"]],"time":"2021-04-02T01:29:51.991842Z"}
{"type":"l2update","product_id":"BTC-USD","changes":[["sell","58828.41","0.22767935"]],"time":"2021-04-02T01:29:51.991998Z"}
{"type":"l2update","product_id":"BTC-USD","changes":[["sell","58828.41","0.28600547"]],"time":"2021-04-02T01:29:51.995593Z"}
{"type":"l2update","product_id":"BTC-USD","changes":[["sell","58867.81","0.00000000"]],"time":"2021-04-02T01:29:52.001139Z"}
{"type":"l2update","product_id":"BTC-USD","changes":[["buy","58802.24","0.00000000"]],"time":"2021-04-02T01:29:52.001468Z"}
{"type":"l2update","product_id":"BTC-USD","changes":[["sell","59520.37","0.01000000"]],"time":"2021-04-02T01:29:52.003472Z"}
{"type":"l2update","product_id":"BTC-USD","changes":[["sell","58845.43","0.00000000"]],"time":"2021-04-02T01:29:52.005533Z"}
{"type":"l2update","product_id":"BTC-USD","changes":[["sell","59022.32","0.00000000"]],"time":"2021-04-02T01:29:52.014777Z"}
{"type":"l2update","product_id":"BTC-USD","changes":[["sell","58958.99","0.00000000"]],"time":"2021-04-02T01:29:52.026457Z"}
{"type":"l2update","product_id":"BTC-USD","changes":[["sell","58974.89","0.01340611"]],"time":"2021-04-02T01:29:52.026609Z"}
{"type":"l2update","product_id":"BTC-USD","changes":[["sell","58988.08","0.01438296"]],"time":"2021-04-02T01:29:52.038072Z"}
{"type":"l2update","product_id":"BTC-USD","changes":[["sell","58828.41","0.22767935"]],"time":"2021-04-02T01:29:52.039503Z"}
{"type":"l2update","product_id":"BTC-USD","changes":[["sell","58828.41","0.26064629"]],"time":"2021-04-02T01:29:52.048318Z"}
{"type":"l2update","product_id":"BTC-USD","changes":[["buy","58692.54","0.00000000"]],"time":"2021-04-02T01:29:52.048978Z"}
{"type":"l2update","product_id":"BTC-USD","changes":[["sell","58974.89","0.00000000"]],"time":"2021-04-02T01:29:52.055385Z"}
{"type":"l2update","product_id":"BTC-USD","changes":[["buy","58717.53","0.01000000"]],"time":"2021-04-02T01:29:52.065314Z"}
{"type":"l2update","product_id":"BTC-USD","changes":[["buy","58512.09","0.00000000"]],"time":"2021-04-02T01:29:52.070292Z"}
{"type":"l2update","product_id":"BTC-USD","changes":[["sell","58828.41","0.22767935"]],"time":"2021-04-02T01:29:52.072989Z"}
{"type":"l2update","product_id":"BTC-USD","changes":[["sell","59026.04","0.05051800"]],"time":"2021-04-02T01:29:52.073469Z"}
{"type":"l2update","product_id":"BTC-USD","changes":[["sell","58828.41","0.28600547"]],"time":"2021-04-02T01:29:52.081575Z"}
{"type":"l2update","product_id":"BTC-USD","changes":[["buy","58532.72","0.04840000"]],"time":"2021-04-02T01:29:52.081790Z"}
{"type":"l2update","product_id":"BTC-USD","changes":[["sell","58867.81","0.70198112"]],"time":"2021-04-02T01:29:52.085201Z"}
{"type":"l2update","product_id":"BTC-USD","changes":[["sell","58990.31","0.00000000"]],"time":"2021-04-02T01:29:52.091854Z"}
{"type":"l2update","product_id":"BTC-USD","changes":[["buy","58802.24","0.41000000"]],"time":"2021-04-02T01:29:52.107204Z"}
{"type":"l2update","product_id":"BTC-USD","changes":[["sell","59008.46","0.01000000"]],"time":"2021-04-02T01:29:52.107330Z"}
{"type":"l2update","product_id":"BTC-USD","changes":[["buy","58698.93","0.00000000"]],"time":"2021-04-02T01:29:52.111949Z"}
{"type":"l2update","product_id":"BTC-USD","changes":[["sell","58844.85","0.41610000"]],"time":"2021-04-02T01:29:52.119392Z"}
{"type":"l2update","product_id":"BTC-USD","changes":[["buy","58717.00","0.01502400"]],"time":"2021-04-02T01:29:52.123407Z"}
{"type":"l2update","product_id":"BTC-USD","changes":[["sell","59026.04","0.00000000"]],"time":"2021-04-02T01:29:52.132029Z"}
{"type":"l2update","product_id":"BTC-USD","changes":[["buy","58717.53","0.00000000"]],"time":"2021-04-02T01:29:52.135211Z"}
{"type":"l2update","product_id":"BTC-USD","changes":[["buy","58717.00","0.00000000"]],"time":"2021-04-02T01:29:52.161463Z"}
{"type":"l2update","product_id":"BTC-USD","changes":[["sell","58828.41","0.22767935"]],"time":"2021-04-02T01:29:52.167532Z"}
{"type":"l2update","product_id":"BTC-USD","changes":[["buy","58802.24","0.00000000"]],"time":"2021-04-02T01:29:52.176351Z"}
{"type":"l2update","product_id":"BTC-USD","changes":[["sell","58844.85","0.00000000"]],"time":"2021-04-02T01:29:52.179367Z"}
{"type":"l2update","product_id":"BTC-USD","changes":[["sell","58947.86","0.01000000"]],"time":"2021-04-02T01:29:52.185784Z"}
{"type":"l2update","product_id":"BTC-USD","changes":[["sell","58828.41","0.26064629"]],"time":"2021-04-02T01:29:52.189554Z"}
{"type":"l2update","product_id":"BTC-USD","changes":[["buy","58657.72","0.01000000"]],"time":"2021-04-02T01:29:52.193091Z"}
{"type":"l2update","product_id":"BTC-USD","changes":[["buy","58647.91","0.05065200"]],"time":"2021-04-02T01:29:52.196802Z"}
{"type":"l2update","product_id":"BTC-USD","changes":[["buy","58623.74","0.00000000"]],"time":"2021-04-02T01:29:52.198009Z"}
{"type":"l2update","product_id":"BTC-USD","changes":[["buy","58644.98","0.01000000"]],"time":"2021-04-02T01:29:52.220178Z"}
{"type":"l2update","product_id":"BTC-USD","changes":[["sell","58828.41","0.22767935"]],"time":"2021-04-02T01:29:52.265941Z"}
{"type":"l2update","product_id":"BTC-USD","changes":[["buy","58802.90","0.42120000"]],"time":"2021-04-02T01:29:52.273271Z"}
{"type":"l2update","product_id":"BTC-USD","changes":[["sell","58828.41","0.28600547"]],"time":"2021-04-02T01:29:52.273315Z"}
{"type":"l2update","product_id":"BTC-USD","changes":[["sell","58828.41","0.22767935"]],"time":"2021-04-02T01:29:52.293926Z"}
{"type":"l2update","product_id":"BTC-USD","changes":[["sell","58828.41","0.26064629"]],"time":"2021-04-02T01:29:52.302145Z"}
{"type":"l2update","product_id":"BTC-USD","changes":[["sell","58844.83","0.44850000"]],"time":"2021-04-02T01:29:52.306239Z"}
{"type":"l2update","product_id":"BTC-USD","changes":[["sell","58828.41","0.22767935"]],"time":"2021-04-02T01:29:52.307454Z"}
{"type":"l2update","product_id":"BTC-USD","changes":[["sell","58828.41","0.28600547"]],"time":"2021-04-02T01:29:52.310790Z"}
{"type":"l2update","product_id":"BTC-USD","changes":[["buy","58647.91","0.00000000"]],"time":"2021-04-02T01:29:52.313314Z"}
{"type":"l2update","product_id":"BTC-USD","changes":[["sell","58828.41","0.22767935"]],"time":"2021-04-02T01:29:52.315502Z"}
{"type":"l2update","product_id":"BTC-USD","changes":[["buy","58802.90","0.00000000"]],"time":"2021-04-02T01:29:52.321322Z"}
{"type":"l2update","product_id":"BTC-USD","changes":[["buy","58667.19","0.04006800"]],"time":"2021-04-02T01:29:52.323552Z"}
{"type":"l2update","product_id":"BTC-USD","changes":[["sell","58844.83","0.00000000"]],"time":"2021-04-02T01:29:52.324808Z"}
{"type":"l2update","product_id":"BTC-USD","changes":[["sell","58828.41","0.31897241"]],"time":"2021-04-02T01:29:52.341008Z"}
{"type":"l2update","product_id":"BTC-USD","changes":[["sell","58828.41","0.22767935"]],"time":"2021-04-02T01:29:52.345331Z"}
{"type":"l2update","product_id":"BTC-USD","changes":[["sell","58979.17","0.00000000"]],"time":"2021-04-02T01:29:52.345683Z"}
{"type":"l2update","product_id":"BTC-USD","changes":[["sell","58998.55","0.01000000"]],"time":"2021-04-02T01:29:52.358061Z"}
{"type":"l2update","product_id":"BTC-USD","changes":[["sell","58828.41","0.31897241"]],"time":"2021-04-02T01:29:52.374122Z"}
{"type":"l2update","product_id":"BTC-USD","changes":[["buy","58802.85","0.44350000"]],"time":"2021-04-02T01:29:52.414422Z"}
{"type":"l2update","product_id":"BTC-USD","changes":[["sell","58980.29","0.00000000"]],"time":"2021-04-02T01:29:52.418207Z"}
{"type":"l2update","product_id":"BTC-USD","changes":[["sell","58947.86","0.00000000"]],"time":"2021-04-02T01:29:52.420181Z"}
{"type":"l2update","product_id":"BTC-USD","changes":[["sell","58844.82","0.43290000"]],"time":"2021-04-02T01:29:52.423534Z"}
{"type":"l2update","product_id":"BTC-USD","changes":[["sell","58828.41","0.22767935"]],"time":"2021-04-02T01:29:52.426930Z"}
{"type":"l2update","product_id":"BTC-USD","changes":[["sell","58983.55","0.04066430"]],"time":"2021-04-02T01:29:52.431817Z"}
{"type":"l2update","product_id":"BTC-USD","changes":[["sell","59005.26","0.01000000"]],"time":"2021-04-02T01:29:52.435684Z"}
{"type":"l2update","product_id":"BTC-USD","changes":[["sell","58828.41","0.31897241"]],"time":"2021-04-02T01:29:52.439675Z"}
{"type":"l2update","product_id":"BTC-USD","changes":[["sell","58828.41","0.22767935"]],"time":"2021-04-02T01:29:52.444306Z"}
{"type":"l2update","product_id":"BTC-USD","changes":[["buy","58802.85","0.00000000"]],"time":"2021-04-02T01:29:52.466737Z"}
{"type":"l2update","product_id":"BTC-USD","changes":[["sell","58844.82","0.00000000"]],"time":"2021-04-02T01:29:52.469798Z"}
{"type":"l2update","product_id":"BTC-USD","changes":[["sell","58828.41","0.31897241"]],"time":"2021-04-02T01:29:52.470907Z"}
{"type":"l2update","product_id":"BTC-USD","changes":[["buy","58629.82","0.00000000"]],"time":"2021-04-02T01:29:52.472907Z"}
{"type":"l2update","product_id":"BTC-USD","changes":[["sell","58828.41","0.22767935"]],"time":"2021-04-02T01:29:52.475980Z"}
{"type":"l2update","product_id":"BTC-USD","changes":[["buy","58648.48","0.01000000"]],"time":"2021-04-02T01:29:52.482448Z"}
{"type":"l2update","product_id":"BTC-USD","changes":[["sell","58828.41","0.22686731"]],"time":"2021-04-02T01:29:52.495104Z"}
{"type":"l2update","product_id":"BTC-USD","changes":[["sell","58828.41","0.31816037"]],"time":"2021-04-02T01:29:52.511275Z"}
{"type":"l2update","product_id":"BTC-USD","changes":[["sell","58828.41","0.22686731"]],"time":"2021-04-02T01:29:52.516132Z"}
{"type":"l2update","product_id":"BTC-USD","changes":[["buy","58828.40","0.00000000"]],"time":"2021-04-02T01:29:52.551180Z"}
{"type":"l2update","product_id":"BTC-USD","changes":[["buy","58827.72","0.55403055"]],"time":"2021-04-02T01:29:52.551180Z"}
{"type":"l2update","product_id":"BTC-USD","changes":[["buy","58802.84","0.41210000"]],"time":"2021-04-02T01:29:52.554951Z"}
{"type":"l2update","product_id":"BTC-USD","changes":[["sell","58829.58","0.09129306"]],"time":"2021-04-02T01:29:52.563218Z"}
{"type":"l2update","product_id":"BTC-USD","changes":[["sell","58844.81","0.44320000"]],"time":"2021-04-02T01:29:52.568121Z"}
{"type":"l2update","product_id":"BTC-USD","changes":[["buy","58667.19","0.00000000"]],"time":"2021-04-02T01:29:52.580609Z"}
{"type":"l2update","product_id":"BTC-USD","changes":[["sell","58872.55","0.00000000"]],"time":"2021-04-02T01:29:52.590766Z"}
{"type":"l2update","product_id":"BTC-USD","changes":[["buy","58605.65","0.05071900"]],"time":"2021-04-02T01:29:52.600444Z"}
{"type":"l2update","product_id":"BTC-USD","changes":[["buy","58679.27","0.01000000"]],"time":"2021-04-02T01:29:52.600504Z"}
{"type":"l2update","product_id":"BTC-USD","changes":[["sell","58872.54","0.70703985"]],"time":"2021-04-02T01:29:52.605233Z"}
{"type":"l2update","product_id":"BTC-USD","changes":[["sell","58829.58","0.00000000"]],"time":"2021-04-02T01:29:52.614756Z"}
{"type":"l2update","product_id":"BTC-USD","changes":[["buy","58613.34","0.00000000"]],"time":"2021-04-02T01:29:52.675347Z"}
{"type":"l2update","product_id":"BTC-USD","changes":[["sell","58829.58","0.09129306"]],"time":"2021-04-02T01:29:52.681892Z"}
{"type":"l2update","product_id":"BTC-USD","changes":[["buy","58802.84","0.00000000"]],"time":"2021-04-02T01:29:52.682461Z"}
{"type":"l2update","product_id":"BTC-USD","changes":[["buy","58679.27","0.00000000"]],"time":"2021-04-02T01:29:52.683672Z"}
{"type":"l2update","product_id":"BTC-USD","changes":[["buy","58631.44","0.01489500"]],"time":"2021-04-02T01:29:52.685627Z"}
{"type":"l2update","product_id":"BTC-USD","changes":[["sell","58829.58","0.00000000"]],"time":"2021-04-02T01:29:52.686506Z"}
{"type":"l2update","product_id":"BTC-USD","changes":[["sell","58844.81","0.00000000"]],"time":"2021-04-02T01:29:52.686571Z"}
{"type":"l2update","product_id":"BTC-USD","changes":[["buy","58648.18","0.01000000"]],"time":"2021-04-02T01:29:52.693364Z"}
{"type":"l2update","product_id":"BTC-USD","changes":[["buy","58605.65","0.00000000"]],"time":"2021-04-02T01:29:52.695071Z"}
{"type":"l2update","product_id":"BTC-USD","changes":[["buy","58802.87","0.42150000"]],"time":"2021-04-02T01:29:52.773545Z"}
{"type":"l2update","product_id":"BTC-USD","changes":[["sell","58829.58","0.09129306"]],"time":"2021-04-02T01:29:52.780770Z"}
{"type":"l2update","product_id":"BTC-USD","changes":[["sell","58845.36","0.40850000"]],"time":"2021-04-02T01:29:52.780936Z"}
{"type":"l2update","product_id":"BTC-USD","changes":[["sell","58829.58","0.00000000"]],"time":"2021-04-02T01:29:52.785543Z"}
{"type":"l2update","product_id":"BTC-USD","changes":[["buy","58631.76","0.01000000"]],"time":"2021-04-02T01:29:52.795797Z"}
{"type":"l2update","product_id":"BTC-USD","changes":[["buy","58817.14","0.08400000"]],"time":"2021-04-02T01:29:52.795816Z"}
{"type":"l2update","product_id":"BTC-USD","changes":[["buy","58802.87","0.00000000"]],"time":"2021-04-02T01:29:52.806337Z"}
{"type":"l2update","product_id":"BTC-USD","changes":[["sell","58845.36","0.00000000"]],"time":"2021-04-02T01:29:52.809585Z"}
{"type":"l2update","product_id":"BTC-USD","changes":[["sell","59024.42","0.00000000"]],"time":"2021-04-02T01:29:52.818139Z"}
{"type":"l2update","product_id":"BTC-USD","changes":[["buy","58764.28","0.00000000"]],"time":"2021-04-02T01:29:52.825120Z"}
{"type":"l2update","product_id":"BTC-USD","changes":[["sell","59042.63","0.01485000"]],"time":"2021-04-02T01:29:52.827307Z"}
{"type":"l2update","product_id":"BTC-USD","changes":[["buy","58786.48","0.70520000"]],"time":"2021-04-02T01:29:52.850773Z"}
{"type":"l2update","product_id":"BTC-USD","changes":[["sell","59520.37","0.00000000"]],"time":"2021-04-02T01:29:52.879797Z"}
{"type":"l2update","product_id":"BTC-USD","changes":[["buy","58648.48","0.00000000"]],"time":"2021-04-02T01:29:52.883105Z"}
{"type":"l2update","product_id":"BTC-USD","changes":[["sell","59488.06","0.01000000"]],"time":"2021-04-02T01:29:52.890107Z"}
{"type":"l2update","product_id":"BTC-USD","changes":[["buy","58667.13","0.01000000"]],"time":"2021-04-02T01:29:52.893652Z"}
{"type":"l2update","product_id":"BTC-USD","changes":[["buy","58803.01","0.44420000"]],"time":"2021-04-02T01:29:52.897613Z"}
{"type":"l2update","product_id":"BTC-USD","changes":[["sell","58829.58","0.09129306"]],"time":"2021-04-02T01:29:52.905106Z"}
{"type":"l2update","product_id":"BTC-USD","changes":[["sell","58845.35","0.44530000"]],"time":"2021-04-02T01:29:52.908799Z"}
{"type":"l2update","product_id":"BTC-USD","changes":[["sell","58829.58","0.00000000"]],"time":"2021-04-02T01:29:52.910121Z"}
{"type":"l2update","product_id":"BTC-USD","changes":[["buy","58644.98","0.00000000"]],"time":"2021-04-02T01:29:52.917613Z"}
{"type":"l2update","product_id":"BTC-USD","changes":[["sell","59488.06","0.00000000"]],"time":"2021-04-02T01:29:52.920850Z"}
{"type":"l2update","product_id":"BTC-USD","changes":[["buy","58613.12","0.08530512"]],"time":"2021-04-02T01:29:52.928080Z"}
{"type":"l2update","product_id":"BTC-USD","changes":[["sell","58977.95","0.00000000"]],"time":"2021-04-02T01:29:52.937446Z"}
{"type":"l2update","product_id":"BTC-USD","changes":[["sell","59520.37","0.01000000"]],"time":"2021-04-02T01:29:52.942406Z"}
{"type":"l2update","product_id":"BTC-USD","changes":[["sell","59009.03","0.00847327"]],"time":"2021-04-02T01:29:52.950088Z"}
{"type":"l2update","product_id":"BTC-USD","changes":[["sell","58829.58","0.09129306"]],"time":"2021-04-02T01:29:52.964815Z"}
{"type":"l2update","product_id":"BTC-USD","changes":[["sell","58829.58","0.00000000"]],"time":"2021-04-02T01:29:52.969398Z"}
{"type":"l2update","product_id":"BTC-USD","changes":[["sell","58829.58","0.09129306"]],"time":"2021-04-02T01:29:52.990949Z"}
{"type":"l2update","product_id":"BTC-USD","changes":[["buy","58631.76","0.00000000"]],"time":"2021-04-02T01:29:52.991560Z"}
{"type":"l2update","product_id":"BTC-USD","changes":[["sell","58867.81","0.00000000"]],"time":"2021-04-02T01:29:52.998484Z"}
{"type":"l2update","product_id":"BTC-USD","changes":[["buy","58613.03","0.01000000"]],"time":"2021-04-02T01:29:53.002057Z"}
{"type":"l2update","product_id":"BTC-USD","changes":[["sell","58829.58","0.00000000"]],"time":"2021-04-02T01:29:53.028254Z"}
{"type":"l2update","product_id":"BTC-USD","changes":[["sell","58829.58","0.09129306"]],"time":"2021-04-02T01:29:53.039895Z"}
{"type":"l2update","product_id":"BTC-USD","changes":[["sell","58829.58","0.00000000"]],"time":"2021-04-02T01:29:53.044566Z"}
{"type":"l2update","product_id":"BTC-USD","changes":[["sell","58867.81","0.99852157"]],"time":"2021-04-02T01:29:53.084347Z"}
{"type":"l2update","product_id":"BTC-USD","changes":[["sell","58836.32","0.00000000"]],"time":"2021-04-02T01:29:53.092925Z"}
{"type":"l2update","product_id":"BTC-USD","changes":[["sell","58835.45","0.08498278"]],"time":"2021-04-02T01:29:53.106898Z"}
{"type":"l2update","product_id":"BTC-USD","changes":[["buy","58613.12","0.00000000"]],"time":"2021-04-02T01:29:53.123398Z"}
{"type":"l2update","product_id":"BTC-USD","changes":[["buy","58656.36","0.00000000"]],"time":"2021-04-02T01:29:53.143991Z"}
{"type":"l2update","product_id":"BTC-USD","changes":[["buy","58623.74","0.01247380"]],"time":"2021-04-02T01:29:53.147884Z"}
{"type":"l2update","product_id":"BTC-USD","changes":[["sell","59520.37","0.00000000"]],"time":"2021-04-02T01:29:53.151489Z"}
{"type":"l2update","product_id":"BTC-USD","changes":[["buy","58674.80","0.03069100"]],"time":"2021-04-02T01:29:53.158163Z"}
{"type":"l2update","product_id":"BTC-USD","changes":[["sell","59488.06","0.01000000"]],"time":"2021-04-02T01:29:53.168489Z"}
{"type":"l2update","product_id":"BTC-USD","changes":[["sell","58829.58","0.09129306"]],"time":"2021-04-02T01:29:53.175982Z"}
{"type":"l2update","product_id":"BTC-USD","changes":[["buy","58828.40","0.00956294"]],"time":"2021-04-02T01:29:53.243943Z"}
{"type":"l2update","product_id":"BTC-USD","changes":[["buy","58828.40","0.01279000"]],"time":"2021-04-02T01:29:53.246903Z"}
{"type":"l2update","product_id":"BTC-USD","changes":[["sell","58829.58","0.00000000"]],"time":"2021-04-02T01:29:53.250744Z"}
{"type":"l2update","product_id":"BTC-USD","changes":[["buy","58828.40","0.00322706"]],"time":"2021-04-02T01:29:53.251545Z"}
{"type":"l2update","product_id":"BTC-USD","changes":[["buy","58828.40","0.00000000"]],"time":"2021-04-02T01:29:53.252107Z"}
{"type":"l2update","product_id":"BTC-USD","changes":[["buy","58648.18","0.00000000"]],"time":"2021-04-02T01:29:53.253846Z"}
{"type":"l2update","product_id":"BTC-USD","changes":[["sell","58986.24","0.00000000"]],"time":"2021-04-02T01:29:53.256665Z"}
{"type":"l2update","product_id":"BTC-USD","changes":[["sell","58828.41","0.25983425"]],"time":"2021-04-02T01:29:53.258183Z"}
{"type":"l2update","product_id":"BTC-USD","changes":[["buy","58828.40","0.00826806"]],"time":"2021-04-02T01:29:53.262005Z"}
{"type":"l2update","product_id":"BTC-USD","changes":[["buy","58671.50","0.01000000"]],"time":"2021-04-02T01:29:53.262041Z"}
{"type":"l2update","product_id":"BTC-USD","changes":[["buy","58803.01","0.00000000"]],"time":"2021-04-02T01:29:53.262585Z"}
{"type":"l2update","product_id":"BTC-USD","changes":[["sell","58828.41","0.22686731"]],"time":"2021-04-02T01:29:53.262603Z"}
{"type":"l2update","product_id":"BTC-USD","changes":[["sell","58829.58","0.09129306"]],"time":"2021-04-02T01:29:53.262671Z"}
{"type":"l2update","product_id":"BTC-USD","changes":[["sell","58964.92","0.00847961"]],"time":"2021-04-02T01:29:53.265905Z"}
{"type":"l2update","product_id":"BTC-USD","changes":[["sell","58845.35","0.00000000"]],"time":"2021-04-02T01:29:53.266395Z"}
{"type":"l2update","product_id":"BTC-USD","changes":[["sell","58829.58","0.00000000"]],"time":"2021-04-02T01:29:53.267236Z"}
{"type":"l2update","product_id":"BTC-USD","changes":[["buy","58828.40","0.00000000"]],"time":"2021-04-02T01:29:53.268719Z"}
{"type":"l2update","product_id":"BTC-USD","changes":[["sell","58828.41","0.25983425"]],"time":"2021-04-02T01:29:53.275528Z"}
{"type":"l2update","product_id":"BTC-USD","changes":[["buy","58827.73","0.02743037"]],"time":"2021-04-02T01:29:53.275600Z"}
{"type":"l2update","product_id":"BTC-USD","changes":[["sell","58828.41","0.22686731"]],"time":"2021-04-02T01:29:53.279676Z"}
{"type":"l2update","product_id":"BTC-USD","changes":[["sell","58829.58","0.09129306"]],"time":"2021-04-02T01:29:53.279706Z"}
{"type":"l2update","product_id":"BTC-USD","changes":[["buy","58827.73","0.00000000"]],"time":"2021-04-02T01:29:53.280632Z"}
{"type":"l2update","product_id":"BTC-USD","changes":[["sell","58829.58","0.00000000"]],"time":"2021-04-02T01:29:53.283660Z"}
{"type":"l2update","product_id":"BTC-USD","changes":[["sell","58835.45","0.00000000"]],"time":"2021-04-02T01:29:53.298252Z"}
{"type":"l2update","product_id":"BTC-USD","changes":[["buy","58768.04","0.10000000"]],"time":"2021-04-02T01:29:53.303693Z"}
{"type":"l2update","product_id":"BTC-USD","changes":[["sell","58912.95","0.10000000"]],"time":"2021-04-02T01:29:53.312696Z"}
{"type":"l2update","product_id":"BTC-USD","changes":[["sell","58836.32","0.08498152"]],"time":"2021-04-02T01:29:53.317544Z"}
{"type":"l2update","product_id":"BTC-USD","changes":[["buy","58803.03","0.44920000"]],"time":"2021-04-02T01:29:53.354588Z"}
{"type":"l2update","product_id":"BTC-USD","changes":[["sell","58845.30","0.40430000"]],"time":"2021-04-02T01:29:53.366881Z"}
{"type":"l2update","product_id":"BTC-USD","changes":[["buy","58803.03","0.00000000"]],"time":"2021-04-02T01:29:53.370382Z"}
{"type":"l2update","product_id":"BTC-USD","changes":[["sell","58845.30","0.00000000"]],"time":"2021-04-02T01:29:53.373971Z"}
{"type":"l2update","product_id":"BTC-USD","changes":[["sell","58829.58","0.09129306"]],"time":"2021-04-02T01:29:53.375124Z"}
{"type":"l2update","product_id":"BTC-USD","changes":[["sell","58998.55","0.00000000"]],"time":"2021-04-02T01:29:53.377290Z"}
{"type":"l2update","product_id":"BTC-USD","changes":[["sell","58980.33","0.01000000"]],"time":"2021-04-02T01:29:53.386217Z"}
{"type":"l2update","product_id":"BTC-USD","changes":[["sell","58964.92","0.00000000"]],"time":"2021-04-02T01:29:53.388129Z"}
{"type":"l2update","product_id":"BTC-USD","changes":[["sell","58986.24","0.00847655"]],"time":"2021-04-02T01:29:53.397825Z"}
{"type":"l2update","product_id":"BTC-USD","changes":[["sell","59005.26","0.00000000"]],"time":"2021-04-02T01:29:53.455853Z"}
{"type":"l2update","product_id":"BTC-USD","changes":[["buy","58803.02","0.41610000"]],"time":"2021-04-02T01:29:53.462155Z"}
{"type":"l2update","product_id":"BTC-USD","changes":[["sell","58845.29","0.44560000"]],"time":"2021-04-02T01:29:53.470441Z"}
{"type":"l2update","product_id":"BTC-USD","changes":[["sell","58986.53","0.01000000"]],"time":"2021-04-02T01:29:53.470492Z"}
{"type":"l2update","product_id":"BTC-USD","changes":[["buy","58821.79","0.00000000"]],"time":"2021-04-02T01:29:53.563322Z"}
{"type":"l2update","product_id":"BTC-USD","changes":[["sell","58829.58","0.00000000"]],"time":"2021-04-02T01:29:53.565273Z"}
{"type":"l2update","product_id":"BTC-USD","changes":[["buy","58822.91","0.24995469"]],"time":"2021-04-02T01:29:53.572659Z"}
{"type":"l2update","product_id":"BTC-USD","changes":[["buy","58674.80","0.00000000"]],"time":"2021-04-02T01:29:53.577470Z"}
{"type":"l2update","product_id":"BTC-USD","changes":[["buy","58695.25","0.03069100"]],"time":"2021-04-02T01:29:53.587057Z"}
{"type":"l2update","product_id":"BTC-USD","changes":[["buy","58803.02","0.00000000"]],"time":"2021-04-02T01:29:53.610725Z"}
{"type":"l2update","product_id":"BTC-USD","changes":[["sell","58845.29","0.00000000"]],"time":"2021-04-02T01:29:53.613911Z"}
{"type":"l2update","product_id":"BTC-USD","changes":[["sell","58828.41","0.12686731"]],"time":"2021-04-02T01:29:53.634774Z"}
{"type":"l2update","product_id":"BTC-USD","changes":[["sell","58835.14","0.10000000"]],"time":"2021-04-02T01:29:53.648527Z"}
{"type":"l2update","product_id":"BTC-USD","changes":[["sell","58829.58","0.09129306"]],"time":"2021-04-02T01:29:53.652283Z"}
{"type":"l2update","product_id":"BTC-USD","changes":[["sell","58829.58","0.00000000"]],"time":"2021-04-02T01:29:53.665285Z"}
{"type":"l2update","product_id":"BTC-USD","changes":[["buy","58822.91","0.00000000"]],"time":"2021-04-02T01:29:53.667803Z"}
{"type":"l2update","product_id":"BTC-USD","changes":[["sell","58828.41","0.07767935"]],"time":"2021-04-02T01:29:53.677238Z"}
{"type":"l2update","product_id":"BTC-USD","changes":[["buy","58821.67","0.24995469"]],"time":"2021-04-02T01:29:53.678695Z"}
{"type":"l2update","product_id":"BTC-USD","changes":[["sell","58836.32","0.00000000"]],"time":"2021-04-02T01:29:53.685582Z"}
{"type":"l2update","product_id":"BTC-USD","changes":[["sell","59488.06","0.00000000"]],"time":"2021-04-02T01:29:53.686474Z"}
{"type":"l2update","product_id":"BTC-USD","changes":[["sell","58919.74","0.00000000"]],"time":"2021-04-02T01:29:53.697117Z"}
{"type":"l2update","product_id":"BTC-USD","changes":[["sell","59520.37","0.08400485"]],"time":"2021-04-02T01:29:53.697164Z"}
{"type":"l2update","product_id":"BTC-USD","changes":[["sell","58835.45","0.08498278"]],"time":"2021-04-02T01:29:53.697221Z"}
{"type":"l2update","product_id":"BTC-USD","changes":[["buy","58803.01","0.44380000"]],"time":"2021-04-02T01:29:53.700833Z"}
{"type":"l2update","product_id":"BTC-USD","changes":[["sell","58845.28","0.43030000"]],"time":"2021-04-02T01:29:53.708820Z"}
{"type":"l2update","product_id":"BTC-USD","changes":[["sell","58920.92","0.83431522"]],"time":"2021-04-02T01:29:53.708947Z"}
{"type":"l2update","product_id":"BTC-USD","changes":[["sell","58835.45","0.00000000"]],"time":"2021-04-02T01:29:53.754655Z"}
{"type":"l2update","product_id":"BTC-USD","changes":[["sell","58836.32","0.08498152"]],"time":"2021-04-02T01:29:53.765156Z"}
{"type":"l2update","product_id":"BTC-USD","changes":[["sell","58829.58","0.09129306"]],"time":"2021-04-02T01:29:53.772652Z"}
{"type":"l2update","product_id":"BTC-USD","changes":[["sell","59042.63","0.00000000"]],"time":"2021-04-02T01:29:53.775222Z"}
{"type":"l2update","product_id":"BTC-USD","changes":[["sell","59024.42","0.01000000"]],"time":"2021-04-02T01:29:53.783590Z"}
{"type":"l2update","product_id":"BTC-USD","changes":[["buy","58631.44","0.00000000"]],"time":"2021-04-02T01:29:53.786869Z"}
{"type":"l2update","product_id":"BTC-USD","changes":[["sell","59520.37","0.00000000"]],"time":"2021-04-02T01:29:53.794730Z"}
{"type":"l2update","product_id":"BTC-USD","changes":[["buy","58613.34","0.01706096"]],"time":"2021-04-02T01:29:53.796666Z"}
{"type":"l2update","product_id":"BTC-USD","changes":[["sell","59498.83","0.01000000"]],"time":"2021-04-02T01:29:53.804451Z"}
{"type":"l2update","product_id":"BTC-USD","changes":[["sell","58836.32","0.00000000"]],"time":"2021-04-02T01:29:53.818657Z"}
{"type":"l2update","product_id":"BTC-USD","changes":[["sell","58835.45","0.08498278"]],"time":"2021-04-02T01:29:53.832165Z"}
{"type":"l2update","product_id":"BTC-USD","changes":[["sell","58835.14","0.00000000"]],"time":"2021-04-02T01:29:53.860686Z"}
{"type":"l2update","product_id":"BTC-USD","changes":[["sell","58829.58","0.00000000"]],"time":"2021-04-02T01:29:53.869884Z"}
{"type":"l2update","product_id":"BTC-USD","changes":[["buy","58803.01","0.00000000"]],"time":"2021-04-02T01:29:53.873738Z"}
{"type":"l2update","product_id":"BTC-USD","changes":[["sell","58829.57","0.10000000"]],"time":"2021-04-02T01:29:53.873808Z"}
{"type":"l2update","product_id":"BTC-USD","changes":[["sell","58845.28","0.00000000"]],"time":"2021-04-02T01:29:53.877436Z"}
{"type":"l2update","product_id":"BTC-USD","changes":[["sell","58829.58","0.09129306"]],"time":"2021-04-02T01:29:53.892591Z"}
{"type":"l2update","product_id":"BTC-USD","changes":[["sell","58829.58","0.00000000"]],"time":"2021-04-02T01:29:53.897275Z"}
{"type":"l2update","product_id":"BTC-USD","changes":[["buy","58803.00","0.44260000"]],"time":"2021-04-02T01:29:53.964705Z"}
{"type":"l2update","product_id":"BTC-USD","changes":[["sell","58845.26","0.42300000"]],"time":"2021-04-02T01:29:53.972144Z"}
{"type":"l2update","product_id":"BTC-USD","changes":[["sell","58829.58","0.09129306"]],"time":"2021-04-02T01:29:53.972456Z"}
{"type":"l2update","product_id":"BTC-USD","changes":[["sell","58835.45","0.00000000"]],"time":"2021-04-02T01:29:53.984788Z"}
{"type":"l2update","product_id":"BTC-USD","changes":[["sell","58836.32","0.08498152"]],"time":"2021-04-02T01:29:53.997322Z"}
{"type":"l2update","product_id":"BTC-USD","changes":[["sell","58829.58","0.00000000"]],"time":"2021-04-02T01:29:54.028772Z"}
{"type":"l2update","product_id":"BTC-USD","changes":[["sell","58836.32","0.00000000"]],"time":"2021-04-02T01:29:54.055090Z"}
{"type":"l2update","product_id":"BTC-USD","changes":[["sell","58829.58","0.09129306"]],"time":"2021-04-02T01:29:54.070461Z"}
{"type":"l2update","product_id":"BTC-USD","changes":[["sell","58835.45","0.08498278"]],"time":"2021-04-02T01:29:54.070492Z"}
{"type":"l2update","product_id":"BTC-USD","changes":[["buy","58613.03","0.00000000"]],"time":"2021-04-02T01:29:54.101572Z"}
{"type":"l2update","product_id":"BTC-USD","changes":[["sell","58986.53","0.00000000"]],"time":"2021-04-02T01:29:54.105950Z"}
{"type":"l2update","product_id":"BTC-USD","changes":[["sell","59009.43","0.01000000"]],"time":"2021-04-02T01:29:54.121566Z"}
{"type":"l2update","product_id":"BTC-USD","changes":[["buy","58683.17","0.01000000"]],"time":"2021-04-02T01:29:54.125691Z"}
{"type":"l2update","product_id":"BTC-USD","changes":[["sell","59498.83","0.00000000"]],"time":"2021-04-02T01:29:54.137900Z"}
{"type":"l2update","product_id":"BTC-USD","changes":[["sell","59009.43","0.00000000"]],"time":"2021-04-02T01:29:54.138701Z"}
{"type":"l2update","product_id":"BTC-USD","changes":[["sell","59477.29","0.01446150"]],"time":"2021-04-02T01:29:54.147573Z"}
{"type":"l2update","product_id":"BTC-USD","changes":[["sell","58980.29","0.01000000"]],"time":"2021-04-02T01:29:54.154773Z"}
{"type":"l2update","product_id":"BTC-USD","changes":[["sell","58829.58","0.00000000"]],"time":"2021-04-02T01:29:54.164536Z"}
{"type":"l2update","product_id":"BTC-USD","changes":[["sell","58829.58","0.09129306"]],"time":"2021-04-02T01:29:54.174650Z"}
{"type":"l2update","product_id":"BTC-USD","changes":[["sell","58829.58","0.00000000"]],"time":"2021-04-02T01:29:54.179438Z"}
{"type":"l2update","product_id":"BTC-USD","changes":[["sell","58980.29","0.00000000"]],"time":"2021-04-02T01:29:54.202905Z"}
{"type":"l2update","product_id":"BTC-USD","changes":[["sell","59007.35","0.01000000"]],"time":"2021-04-02T01:29:54.217099Z"}
{"type":"l2update","product_id":"BTC-USD","changes":[["sell","58827.73","0.01279000"]],"time":"2021-04-02T01:29:54.224618Z"}
{"type":"l2update","product_id":"BTC-USD","changes":[["sell","58928.41","0.00000000"]],"time":"2021-04-02T01:29:54.232884Z"}
{"type":"l2update","product_id":"BTC-USD","changes":[["sell","58829.58","0.09129306"]],"time":"2021-04-02T01:29:54.236306Z"}
{"type":"l2update","product_id":"BTC-USD","changes":[["sell","58927.73","0.01000000"]],"time":"2021-04-02T01:29:54.244086Z"}
{"type":"l2update","product_id":"BTC-USD","changes":[["buy","58811.90","0.00000000"]],"time":"2021-04-02T01:29:54.244474Z"}
{"type":"l2update","product_id":"BTC-USD","changes":[["sell","58835.45","0.00000000"]],"time":"2021-04-02T01:29:54.244474Z"}
{"type":"l2update","product_id":"BTC-USD","changes":[["buy","58808.63","0.08502153"]],"time":"2021-04-02T01:29:54.261087Z"}
{"type":"l2update","product_id":"BTC-USD","changes":[["sell","58833.47","0.08498565"]],"time":"2021-04-02T01:29:54.261087Z"}
{"type":"l2update","product_id":"BTC-USD","changes":[["sell","58829.58","0.00000000"]],"time":"2021-04-02T01:29:54.268002Z"}
{"type":"l2update","product_id":"BTC-USD","changes":[["sell","58872.54","0.00000000"]],"time":"2021-04-02T01:29:54.273053Z"}
{"type":"l2update","product_id":"BTC-USD","changes":[["sell","58872.56","0.70703985"]],"time":"2021-04-02T01:29:54.286852Z"}
{"type":"l2update","product_id":"BTC-USD","changes":[["sell","58829.58","0.09129306"]],"time":"2021-04-02T01:29:54.375617Z"}
{"type":"l2update","product_id":"BTC-USD","changes":[["buy","58808.63","0.00000000"]],"time":"2021-04-02T01:29:54.390550Z"}
{"type":"l2update","product_id":"BTC-USD","changes":[["buy","58809.92","0.08501967"]],"time":"2021-04-02T01:29:54.405369Z"}
{"type":"l2update","product_id":"BTC-USD","changes":[["sell","58872.56","0.00000000"]],"time":"2021-04-02T01:29:54.447685Z"}
{"type":"l2update","product_id":"BTC-USD","changes":[["sell","58829.58","0.00000000"]],"time":"2021-04-02T01:29:54.448164Z"}
{"type":"l2update","product_id":"BTC-USD","changes":[["sell","58872.56","0.70703985"]],"time":"2021-04-02T01:29:54.464366Z"}
{"type":"l2update","product_id":"BTC-USD","changes":[["buy","58613.34","0.00000000"]],"time":"2021-04-02T01:29:54.466168Z"}
{"type":"l2update","product_id":"BTC-USD","changes":[["buy","58595.25","0.01489500"]],"time":"2021-04-02T01:29:54.476553Z"}
{"type":"l2update","product_id":"BTC-USD","changes":[["buy","58714.14","0.00000000"]],"time":"2021-04-02T01:29:54.477496Z"}
{"type":"l2update","product_id":"BTC-USD","changes":[["sell","58829.58","0.09129306"]],"time":"2021-04-02T01:29:54.480367Z"}
{"type":"l2update","product_id":"BTC-USD","changes":[["buy","58648.16","0.01000000"]],"time":"2021-04-02T01:29:54.495036Z"}
{"type":"l2update","product_id":"BTC-USD","changes":[["buy","58803.00","0.00000000"]],"time":"2021-04-02T01:29:54.523857Z"}
{"type":"l2update","product_id":"BTC-USD","changes":[["sell","58845.26","0.00000000"]],"time":"2021-04-02T01:29:54.527380Z"}
{"type":"l2update","product_id":"BTC-USD","changes":[["sell","58829.58","0.00000000"]],"time":"2021-04-02T01:29:54.543017Z"}
{"type":"l2update","product_id":"BTC-USD","changes":[["buy","58657.95","0.00000000"]],"time":"2021-04-02T01:29:54.567498Z"}
{"type":"l2update","product_id":"BTC-USD","changes":[["sell","58833.47","0.00000000"]],"time":"2021-04-02T01:29:54.568318Z"}
{"type":"l2update","product_id":"BTC-USD","changes":[["sell","58968.20","0.00000000"]],"time":"2021-04-02T01:29:54.573499Z"}
{"type":"l2update","product_id":"BTC-USD","changes":[["sell","58829.58","0.09129306"]],"time":"2021-04-02T01:29:54.578803Z"}
{"type":"l2update","product_id":"BTC-USD","changes":[["sell","58835.45","0.08498278"]],"time":"2021-04-02T01:29:54.582118Z"}
{"type":"l2update","product_id":"BTC-USD","changes":[["buy","58676.32","0.01000000"]],"time":"2021-04-02T01:29:54.582255Z"}
{"type":"l2update","product_id":"BTC-USD","changes":[["sell","59477.29","0.00000000"]],"time":"2021-04-02T01:29:54.615227Z"}
{"type":"l2update","product_id":"BTC-USD","changes":[["buy","58802.94","0.40280000"]],"time":"2021-04-02T01:29:54.616923Z"}
{"type":"l2update","product_id":"BTC-USD","changes":[["buy","58595.25","0.00000000"]],"time":"2021-04-02T01:29:54.622257Z"}
{"type":"l2update","product_id":"BTC-USD","changes":[["sell","59498.83","0.08403527"]],"time":"2021-04-02T01:29:54.627088Z"}
{"type":"l2update","product_id":"BTC-USD","changes":[["sell","58845.18","0.43190000"]],"time":"2021-04-02T01:29:54.627241Z"}
{"type":"l2update","product_id":"BTC-USD","changes":[["buy","58574.13","0.01489500"]],"time":"2021-04-02T01:29:54.632321Z"}
{"type":"l2update","product_id":"BTC-USD","changes":[["buy","58574.13","0.00000000"]],"time":"2021-04-02T01:29:54.641307Z"}
{"type":"l2update","product_id":"BTC-USD","changes":[["buy","58595.25","0.01489500"]],"time":"2021-04-02T01:29:54.650623Z"}
{"type":"l2update","product_id":"BTC-USD","changes":[["sell","58829.58","0.00000000"]],"time":"2021-04-02T01:29:54.668834Z"}
{"type":"l2update","product_id":"BTC-USD","changes":[["sell","59007.35","0.00000000"]],"time":"2021-04-02T01:29:54.672524Z"}
{"type":"l2update","product_id":"BTC-USD","changes":[["buy","58809.92","0.00000000"]],"time":"2021-04-02T01:29:54.674331Z"}
{"type":"l2update","product_id":"BTC-USD","changes":[["buy","58808.96","0.08502106"]],"time":"2021-04-02T01:29:54.683921Z"}
{"type":"l2update","product_id":"BTC-USD","changes":[["sell","58988.61","0.01000000"]],"time":"2021-04-02T01:29:54.688915Z"}
{"type":"l2update","product_id":"BTC-USD","changes":[["buy","58808.96","0.00000000"]],"time":"2021-04-02T01:29:54.740860Z"}
{"type":"l2update","product_id":"BTC-USD","changes":[["buy","58785.14","0.00000000"]],"time":"2021-04-02T01:29:54.747722Z"}
{"type":"l2update","product_id":"BTC-USD","changes":[["buy","58809.92","0.08501967"]],"time":"2021-04-02T01:29:54.750990Z"}
{"type":"l2update","product_id":"BTC-USD","changes":[["sell","58829.58","0.09129306"]],"time":"2021-04-02T01:29:54.769771Z"}
{"type":"l2update","product_id":"BTC-USD","changes":[["buy","58802.94","0.00000000"]],"time":"2021-04-02T01:29:54.826503Z"}
{"type":"l2update","product_id":"BTC-USD","changes":[["sell","58845.18","0.00000000"]],"time":"2021-04-02T01:29:54.830399Z"}
{"type":"l2update","product_id":"BTC-USD","changes":[["buy","58809.92","0.00000000"]],"time":"2021-04-02T01:29:54.869882Z"}
{"type":"l2update","product_id":"BTC-USD","changes":[["sell","58829.58","0.00000000"]],"time":"2021-04-02T01:29:54.874025Z"}
{"type":"l2update","product_id":"BTC-USD","changes":[["buy","58810.92","0.08501822"]],"time":"2021-04-02T01:29:54.883366Z"}
{"type":"l2update","product_id":"BTC-USD","changes":[["sell","58835.45","0.00000000"]],"time":"2021-04-02T01:29:54.908684Z"}
{"type":"l2update","product_id":"BTC-USD","changes":[["sell","58828.42","0.05000000"]],"time":"2021-04-02T01:29:54.913294Z"}
{"type":"l2update","product_id":"BTC-USD","changes":[["buy","58802.94","0.40470000"]],"time":"2021-04-02T01:29:54.917195Z"}
{"type":"l2update","product_id":"BTC-USD","changes":[["sell","58827.73","0.01247270"]],"time":"2021-04-02T01:29:54.920948Z"}
{"type":"l2update","product_id":"BTC-USD","changes":[["sell","58836.32","0.08498152"]],"time":"2021-04-02T01:29:54.920971Z"}
{"type":"l2update","product_id":"BTC-USD","changes":[["buy","58623.74","0.00000000"]],"time":"2021-04-02T01:29:54.926033Z"}
{"type":"l2update","product_id":"BTC-USD","changes":[["sell","58845.17","0.41560000"]],"time":"2021-04-02T01:29:54.928196Z"}
{"type":"l2update","product_id":"BTC-USD","changes":[["buy","58644.98","0.01000000"]],"time":"2021-04-02T01:29:54.936029Z"}
{"type":"l2update","product_id":"BTC-USD","changes":[["sell","58829.58","0.09129306"]],"time":"2021-04-02T01:29:54.977122Z"}
{"type":"l2update","product_id":"BTC-USD","changes":[["buy","58827.72","0.55247115"]],"time":"2021-04-02T01:29:55.008461Z"}
{"type":"l2update","product_id":"BTC-USD","changes":[["sell","58829.58","0.00000000"]],"time":"2021-04-02T01:29:55.015256Z"}
{"type":"l2update","product_id":"BTC-USD","changes":[["buy","58771.70","0.03548508"]],"time":"2021-04-02T01:29:55.019699Z"}
{"type":"l2update","product_id":"BTC-USD","changes":[["buy","58810.92","0.00000000"]],"time":"2021-04-02T01:29:55.020928Z"}
{"type":"l2update","product_id":"BTC-USD","changes":[["buy","58809.93","0.08501965"]],"time":"2021-04-02T01:29:55.036783Z"}
{"type":"l2update","product_id":"BTC-USD","changes":[["buy","58653.38","0.00000000"]],"time":"2021-04-02T01:29:55.080995Z"}
{"type":"l2update","product_id":"BTC-USD","changes":[["buy","58621.56","0.00852928"]],"time":"2021-04-02T01:29:55.090167Z"}
{"type":"l2update","product_id":"BTC-USD","changes":[["sell","58829.58","0.09129306"]],"time":"2021-04-02T01:29:55.130952Z"}
{"type":"l2update","product_id":"BTC-USD","changes":[["buy","58621.56","0.00000000"]],"time":"2021-04-02T01:29:55.131756Z"}
{"type":"l2update","product_id":"BTC-USD","changes":[["sell","58829.58","0.00000000"]],"time":"2021-04-02T01:29:55.136522Z"}
{"type":"l2update","product_id":"BTC-USD","changes":[["buy","58642.77","0.00852619"]],"time":"2021-04-02T01:29:55.142556Z"}
{"type":"l2update","product_id":"BTC-USD","changes":[["buy","56750.00","1.67732859"]],"time":"2021-04-02T01:29:55.196896Z"}
{"type":"l2update","product_id":"BTC-USD","changes":[["buy","58695.25","0.00000000"]],"time":"2021-04-02T01:29:55.197539Z"}
{"type":"l2update","product_id":"BTC-USD","changes":[["sell","58829.58","0.09129306"]],"time":"2021-04-02T01:29:55.200553Z"}
{"type":"l2update","product_id":"BTC-USD","changes":[["sell","58829.58","0.00000000"]],"time":"2021-04-02T01:29:55.205284Z"}
{"type":"l2update","product_id":"BTC-USD","changes":[["buy","58674.70","0.01000000"]],"time":"2021-04-02T01:29:55.207576Z"}
{"type":"l2update","product_id":"BTC-USD","changes":[["sell","58986.24","0.00000000"]],"time":"2021-04-02T01:29:55.218086Z"}
{"type":"l2update","product_id":"BTC-USD","changes":[["sell","59007.17","0.00847354"]],"time":"2021-04-02T01:29:55.226823Z"}
{"type":"l2update","product_id":"BTC-USD","changes":[["sell","58827.73","0.00000000"]],"time":"2021-04-02T01:29:55.230814Z"}
{"type":"l2update","product_id":"BTC-USD","changes":[["sell","58927.73","0.00000000"]],"time":"2021-04-02T01:29:55.238817Z"}
{"type":"l2update","product_id":"BTC-USD","changes":[["sell","58928.41","0.00100000"]],"time":"2021-04-02T01:29:55.250054Z"}
{"type":"l2update","product_id":"BTC-USD","changes":[["sell","58872.56","0.00000000"]],"time":"2021-04-02T01:29:55.272621Z"}
{"type":"l2update","product_id":"BTC-USD","changes":[["sell","58829.58","0.09129306"]],"time":"2021-04-02T01:29:55.273734Z"}
{"type":"l2update","product_id":"BTC-USD","changes":[["buy","58809.93","0.00000000"]],"time":"2021-04-02T01:29:55.274827Z"}
{"type":"l2update","product_id":"BTC-USD","changes":[["sell","58829.58","0.00000000"]],"time":"2021-04-02T01:29:55.278284Z"}
{"type":"l2update","product_id":"BTC-USD","changes":[["buy","58644.98","0.00000000"]],"time":"2021-04-02T01:29:55.284011Z"}
{"type":"l2update","product_id":"BTC-USD","changes":[["buy","58810.93","0.08501821"]],"time":"2021-04-02T01:29:55.286672Z"}
{"type":"l2update","product_id":"BTC-USD","changes":[["sell","58872.56","0.70703985"]],"time":"2021-04-02T01:29:55.290628Z"}
{"type":"l2update","product_id":"BTC-USD","changes":[["buy","58623.74","0.01000000"]],"time":"2021-04-02T01:29:55.294643Z"}
{"type":"l2update","product_id":"BTC-USD","changes":[["buy","58828.40","0.01279000"]],"time":"2021-04-02T01:29:55.309424Z"}
{"type":"l2update","product_id":"BTC-USD","changes":[["sell","58828.41","0.16897241"]],"time":"2021-04-02T01:29:55.320766Z"}
{"type":"l2update","product_id":"BTC-USD","changes":[["sell","59007.17","0.00000000"]],"time":"2021-04-02T01:29:55.344819Z"}
{"type":"l2update","product_id":"BTC-USD","changes":[["sell","58829.57","0.00000000"]],"time":"2021-04-02T01:29:55.352660Z"}
{"type":"l2update","product_id":"BTC-USD","changes":[["sell","58872.56","0.00000000"]],"time":"2021-04-02T01:29:55.353088Z"}
{"type":"l2update","product_id":"BTC-USD","changes":[["sell","58828.41","0.07767935"]],"time":"2021-04-02T01:29:55.358229Z"}
{"type":"l2update","product_id":"BTC-USD","changes":[["sell","58986.24","0.00847655"]],"time":"2021-04-02T01:29:55.359870Z"}
{"type":"l2update","product_id":"BTC-USD","changes":[["sell","58828.41","0.12767935"]],"time":"2021-04-02T01:29:55.367836Z"}
{"type":"l2update","product_id":"BTC-USD","changes":[["sell","58835.14","0.10000000"]],"time":"2021-04-02T01:29:55.367921Z"}
{"type":"l2update","product_id":"BTC-USD","changes":[["sell","58872.56","0.70703985"]],"time":"2021-04-02T01:29:55.367956Z"}
{"type":"l2update","product_id":"BTC-USD","changes":[["sell","58828.41","0.21897241"]],"time":"2021-04-02T01:29:55.375448Z"}
{"type":"l2update","product_id":"BTC-USD","changes":[["sell","58828.42","0.00000000"]],"time":"2021-04-02T01:29:55.376728Z"}
{"type":"l2update","product_id":"BTC-USD","changes":[["sell","58828.41","0.12767935"]],"time":"2021-04-02T01:29:55.379892Z"}
{"type":"l2update","product_id":"BTC-USD","changes":[["sell","58867.81","0.00000000"]],"time":"2021-04-02T01:29:55.386858Z"}
{"type":"l2update","product_id":"BTC-USD","changes":[["sell","58839.11","0.00000000"]],"time":"2021-04-02T01:29:55.434215Z"}
{"type":"l2update","product_id":"BTC-USD","changes":[["buy","58828.40","0.02558000"]],"time":"2021-04-02T01:29:55.435571Z"}
{"type":"l2update","product_id":"BTC-USD","changes":[["buy","58671.50","0.00000000"]],"time":"2021-04-02T01:29:55.437990Z"}
{"type":"l2update","product_id":"BTC-USD","changes":[["sell","58828.41","0.21897241"]],"time":"2021-04-02T01:29:55.439516Z"}
{"type":"l2update","product_id":"BTC-USD","changes":[["sell","58831.40","0.00000000"]],"time":"2021-04-02T01:29:55.441362Z"}
{"type":"l2update","product_id":"BTC-USD","changes":[["sell","58828.41","0.12767935"]],"time":"2021-04-02T01:29:55.444337Z"}
{"type":"l2update","product_id":"BTC-USD","changes":[["sell","58834.82","0.15763862"]],"time":"2021-04-02T01:29:55.451714Z"}
{"type":"l2update","product_id":"BTC-USD","changes":[["buy","58827.73","0.02716241"]],"time":"2021-04-02T01:29:55.455555Z"}
{"type":"l2update","product_id":"BTC-USD","changes":[["buy","58802.94","0.00000000"]],"time":"2021-04-02T01:29:55.462510Z"}
{"type":"l2update","product_id":"BTC-USD","changes":[["sell","58867.81","0.70198112"]],"time":"2021-04-02T01:29:55.471183Z"}
{"type":"l2update","product_id":"BTC-USD","changes":[["buy","58799.84","0.40690000"]],"time":"2021-04-02T01:29:55.471383Z"}
{"type":"l2update","product_id":"BTC-USD","changes":[["sell","58845.17","0.00000000"]],"time":"2021-04-02T01:29:55.476211Z"}
{"type":"l2update","product_id":"BTC-USD","changes":[["sell","58980.33","0.00000000"]],"time":"2021-04-02T01:29:55.476949Z"}
{"type":"l2update","product_id":"BTC-USD","changes":[["sell","58828.41","0.21897241"]],"time":"2021-04-02T01:29:55.478790Z"}
{"type":"l2update","product_id":"BTC-USD","changes":[["sell","58828.41","0.12767935"]],"time":"2021-04-02T01:29:55.483445Z"}
{"type":"l2update","product_id":"BTC-USD","changes":[["sell","58962.41","0.01000000"]],"time":"2021-04-02T01:29:55.487087Z"}
{"type":"l2update","product_id":"BTC-USD","changes":[["sell","58843.23","0.40510000"]],"time":"2021-04-02T01:29:55.487204Z"}
{"type":"l2update","product_id":"BTC-USD","changes":[["sell","58828.41","0.21897241"]],"time":"2021-04-02T01:29:55.494177Z"}
{"type":"l2update","product_id":"BTC-USD","changes":[["sell","58828.41","0.12767935"]],"time":"2021-04-02T01:29:55.498652Z"}
{"type":"l2update","product_id":"BTC-USD","changes":[["sell","58843.23","0.00000000"]],"time":"2021-04-02T01:29:55.511424Z"}
{"type":"l2update","product_id":"BTC-USD","changes":[["buy","58799.84","0.00000000"]],"time":"2021-04-02T01:29:55.514583Z"}
{"type":"l2update","product_id":"BTC-USD","changes":[["buy","58821.67","0.00000000"]],"time":"2021-04-02T01:29:55.521203Z"}
{"type":"l2update","product_id":"BTC-USD","changes":[["buy","58826.81","0.24995469"]],"time":"2021-04-02T01:29:55.536671Z"}
{"type":"l2update","product_id":"BTC-USD","changes":[["sell","58828.41","0.21897241"]],"time":"2021-04-02T01:29:55.552189Z"}
{"type":"l2update","product_id":"BTC-USD","changes":[["buy","58817.08","0.00000000"]],"time":"2021-04-02T01:29:55.559082Z"}
{"type":"l2update","product_id":"BTC-USD","changes":[["sell","58828.41","0.12767935"]],"time":"2021-04-02T01:29:55.567554Z"}
{"type":"l2update","product_id":"BTC-USD","changes":[["buy","58824.17","0.06359004"]],"time":"2021-04-02T01:29:55.571874Z"}
{"type":"l2update","product_id":"BTC-USD","changes":[["buy","58683.17","0.00000000"]],"time":"2021-04-02T01:29:55.591459Z"}
{"type":"l2update","product_id":"BTC-USD","changes":[["buy","58709.32","0.01000000"]],"time":"2021-04-02T01:29:55.601121Z"}
{"type":"l2update","product_id":"BTC-USD","changes":[["sell","58846.20","0.40620000"]],"time":"2021-04-02T01:29:55.601295Z"}
{"type":"l2update","product_id":"BTC-USD","changes":[["sell","58828.41","0.21897241"]],"time":"2021-04-02T01:29:55.627429Z"}
{"type":"l2update","product_id":"BTC-USD","changes":[["sell","58828.41","0.12767935"]],"time":"2021-04-02T01:29:55.632283Z"}
{"type":"l2update","product_id":"BTC-USD","changes":[["buy","58803.13","0.43940000"]],"time":"2021-04-02T01:29:55.646448Z"}
{"type":"l2update","product_id":"BTC-USD","changes":[["sell","58867.81","0.00000000"]],"time":"2021-04-02T01:29:55.663289Z"}
{"type":"l2update","product_id":"BTC-USD","changes":[["sell","58828.41","0.21897241"]],"time":"2021-04-02T01:29:55.679999Z"}
{"type":"l2update","product_id":"BTC-USD","changes":[["sell","58828.41","0.12767935"]],"time":"2021-04-02T01:29:55.684184Z"}
{"type":"l2update","product_id":"BTC-USD","changes":[["buy","58816.08","0.50300000"]],"time":"2021-04-02T01:29:55.691520Z"}
{"type":"l2update","product_id":"BTC-USD","changes":[["buy","58810.75","0.04000000"]],"time":"2021-04-02T01:29:55.706700Z"}
{"type":"l2update","product_id":"BTC-USD","changes":[["buy","58803.16","0.00000000"]],"time":"2021-04-02T01:29:55.710795Z"}
{"type":"l2update","product_id":"BTC-USD","changes":[["sell","58829.59","0.00000000"]],"time":"2021-04-02T01:29:55.732375Z"}
{"type":"l2update","product_id":"BTC-USD","changes":[["buy","58817.00","0.00000000"]],"time":"2021-04-02T01:29:55.735993Z"}
{"type":"l2update","product_id":"BTC-USD","changes":[["sell","58828.41","0.21897241"]],"time":"2021-04-02T01:29:55.736976Z"}
{"type":"l2update","product_id":"BTC-USD","changes":[["buy","58823.36","0.00000000"]],"time":"2021-04-02T01:29:55.740279Z"}
{"type":"l2update","product_id":"BTC-USD","changes":[["sell","58828.41","0.12767935"]],"time":"2021-04-02T01:29:55.741487Z"}
{"type":"l2update","product_id":"BTC-USD","changes":[["sell","58829.94","0.00000000"]],"time":"2021-04-02T01:29:55.743163Z"}
{"type":"l2update","product_id":"BTC-USD","changes":[["sell","58831.78","0.34006811"]],"time":"2021-04-02T01:29:55.748808Z"}
{"type":"l2update","product_id":"BTC-USD","changes":[["sell","58867.81","0.16698112"]],"time":"2021-04-02T01:29:55.748947Z"}
{"type":"l2update","product_id":"BTC-USD","changes":[["buy","58826.17","0.01560000"]],"time":"2021-04-02T01:29:55.753053Z"}
{"type":"l2update","product_id":"BTC-USD","changes":[["buy","58819.19","0.34006811"]],"time":"2021-04-02T01:29:55.760853Z"}
{"type":"l2update","product_id":"BTC-USD","changes":[["sell","58832.07","0.01560000"]],"time":"2021-04-02T01:29:55.764866Z"}
{"type":"l2update","product_id":"BTC-USD","changes":[["buy","58817.09","0.00000000"]],"time":"2021-04-02T01:29:55.766531Z"}
{"type":"l2update","product_id":"BTC-USD","changes":[["sell","58831.77","0.09129306"]],"time":"2021-04-02T01:29:55.775949Z"}
{"type":"l2update","product_id":"BTC-USD","changes":[["buy","58820.01","0.24995472"]],"time":"2021-04-02T01:29:55.779679Z"}
{"type":"l2update","product_id":"BTC-USD","changes":[["sell","58831.77","0.00000000"]],"time":"2021-04-02T01:29:55.780302Z"}
{"type":"l2update","product_id":"BTC-USD","changes":[["buy","58682.65","0.00000000"]],"time":"2021-04-02T01:29:55.783457Z"}
{"type":"l2update","product_id":"BTC-USD","changes":[["buy","58705.16","0.01000000"]],"time":"2021-04-02T01:29:55.795177Z"}
{"type":"l2update","product_id":"BTC-USD","changes":[["sell","59498.83","0.00000000"]],"time":"2021-04-02T01:29:55.797026Z"}
{"type":"l2update","product_id":"BTC-USD","changes":[["sell","59477.29","0.01332690"]],"time":"2021-04-02T01:29:55.806685Z"}
{"type":"l2update","product_id":"BTC-USD","changes":[["sell","58988.08","0.00000000"]],"time":"2021-04-02T01:29:55.810451Z"}
{"type":"l2update","product_id":"BTC-USD","changes":[["sell","58831.77","0.09129306"]],"time":"2021-04-02T01:29:55.822788Z"}
{"type":"l2update","product_id":"BTC-USD","changes":[["sell","59013.02","0.01000000"]],"time":"2021-04-02T01:29:55.822839Z"}
{"type":"l2update","product_id":"BTC-USD","changes":[["sell","58831.77","0.00000000"]],"time":"2021-04-02T01:29:55.828255Z"}
{"type":"l2update","product_id":"BTC-USD","changes":[["sell","58912.95","0.00000000"]],"time":"2021-04-02T01:29:55.855089Z"}
{"type":"l2update","product_id":"BTC-USD","changes":[["sell","58831.77","0.09129306"]],"time":"2021-04-02T01:29:55.856469Z"}
{"type":"l2update","product_id":"BTC-USD","changes":[["buy","58768.04","0.00000000"]],"time":"2021-04-02T01:29:55.857815Z"}
{"type":"l2update","product_id":"BTC-USD","changes":[["sell","58831.77","0.00000000"]],"time":"2021-04-02T01:29:55.861394Z"}
{"type":"l2update","product_id":"BTC-USD","changes":[["buy","58772.04","0.10000000"]],"time":"2021-04-02T01:29:55.864656Z"}
{"type":"l2update","product_id":"BTC-USD","changes":[["sell","58916.96","0.10000000"]],"time":"2021-04-02T01:29:55.872098Z"}
{"type":"l2update","product_id":"BTC-USD","changes":[["sell","58831.77","0.09129306"]],"time":"2021-04-02T01:29:55.876031Z"}
{"type":"l2update","product_id":"BTC-USD","changes":[["sell","59013.02","0.00000000"]],"time":"2021-04-02T01:29:55.878806Z"}
{"type":"l2update","product_id":"BTC-USD","changes":[["sell","58831.77","0.00000000"]],"time":"2021-04-02T01:29:55.880012Z"}
{"type":"l2update","product_id":"BTC-USD","changes":[["sell","58992.24","0.01472103"]],"time":"2021-04-02T01:29:55.887866Z"}
{"type":"l2update","product_id":"BTC-USD","changes":[["sell","58831.77","0.09129306"]],"time":"2021-04-02T01:29:55.899236Z"}
{"type":"l2update","product_id":"BTC-USD","changes":[["sell","58831.77","0.00000000"]],"time":"2021-04-02T01:29:55.904575Z"}
{"type":"l2update","product_id":"BTC-USD","changes":[["buy","58803.13","0.00000000"]],"time":"2021-04-02T01:29:55.946676Z"}
{"type":"l2update","product_id":"BTC-USD","changes":[["sell","59009.03","0.00000000"]],"time":"2021-04-02T01:29:55.946766Z"}
{"type":"l2update","product_id":"BTC-USD","changes":[["sell","58846.20","0.00000000"]],"time":"2021-04-02T01:29:55.951294Z"}
{"type":"l2update","product_id":"BTC-USD","changes":[["sell","58867.81","0.00000000"]],"time":"2021-04-02T01:29:55.956959Z"}
{"type":"l2update","product_id":"BTC-USD","changes":[["sell","58831.77","0.09129306"]],"time":"2021-04-02T01:29:55.959746Z"}
{"type":"l2update","product_id":"BTC-USD","changes":[["sell","58988.10","0.01000000"]],"time":"2021-04-02T01:29:55.963351Z"}
{"type":"l2update","product_id":"BTC-USD","changes":[["sell","58831.77","0.00000000"]],"time":"2021-04-02T01:29:55.966391Z"}
{"type":"l2update","product_id":"BTC-USD","changes":[["buy","58648.16","0.00000000"]],"time":"2021-04-02T01:29:55.981292Z"}
{"type":"l2update","product_id":"BTC-USD","changes":[["buy","58826.81","0.00000000"]],"time":"2021-04-02T01:29:55.984449Z"}
{"type":"l2update","product_id":"BTC-USD","changes":[["buy","58824.65","0.24995469"]],"time":"2021-04-02T01:29:55.995809Z"}
{"type":"l2update","product_id":"BTC-USD","changes":[["buy","58793.17","0.00000000"]],"time":"2021-04-02T01:29:55.996249Z"}
{"type":"l2update","product_id":"BTC-USD","changes":[["buy","58695.04","0.01000000"]],"time":"2021-04-02T01:29:56.002404Z"}
{"type":"l2update","product_id":"BTC-USD","changes":[["buy","58803.16","0.04000000"]],"time":"2021-04-02T01:29:56.017389Z"}
{"type":"l2update","product_id":"BTC-USD","changes":[["buy","58810.75","0.00000000"]],"time":"2021-04-02T01:29:56.020100Z"}
{"type":"l2update","product_id":"BTC-USD","changes":[["sell","58828.41","0.12117337"]],"time":"2021-04-02T01:29:56.021337Z"}
{"type":"l2update","product_id":"BTC-USD","changes":[["sell","58831.77","0.09129306"]],"time":"2021-04-02T01:29:56.030772Z"}
{"type":"l2update","product_id":"BTC-USD","changes":[["sell","58831.77","0.00000000"]],"time":"2021-04-02T01:29:56.035231Z"}
{"type":"l2update","product_id":"BTC-USD","changes":[["sell","58867.81","0.76198112"]],"time":"2021-04-02T01:29:56.038569Z"}
{"type":"l2update","product_id":"BTC-USD","changes":[["buy","58804.12","0.40550000"]],"time":"2021-04-02T01:29:56.046796Z"}
{"type":"l2update","product_id":"BTC-USD","changes":[["buy","58750.09","0.00000000"]],"time":"2021-04-02T01:29:56.053348Z"}
{"type":"l2update","product_id":"BTC-USD","changes":[["sell","58846.20","0.42040000"]],"time":"2021-04-02T01:29:56.057985Z"}
{"type":"l2update","product_id":"BTC-USD","changes":[["sell","58831.77","0.09129306"]],"time":"2021-04-02T01:29:56.084899Z"}
{"type":"l2update","product_id":"BTC-USD","changes":[["sell","58831.77","0.00000000"]],"time":"2021-04-02T01:29:56.089600Z"}
{"type":"l2update","product_id":"BTC-USD","changes":[["sell","59477.29","0.00000000"]],"time":"2021-04-02T01:29:56.125180Z"}
{"type":"l2update","product_id":"BTC-USD","changes":[["sell","58920.92","0.00000000"]],"time":"2021-04-02T01:29:56.133949Z"}
{"type":"l2update","product_id":"BTC-USD","changes":[["sell","58992.24","0.00000000"]],"time":"2021-04-02T01:29:56.134959Z"}
{"type":"l2update","product_id":"BTC-USD","changes":[["sell","58828.41","0.12190999"]],"time":"2021-04-02T01:29:56.135469Z"}
{"type":"l2update","product_id":"BTC-USD","changes":[["sell","59498.83","0.08403527"]],"time":"2021-04-02T01:29:56.135482Z"}
{"type":"l2update","product_id":"BTC-USD","changes":[["buy","58750.09","1.00000000"]],"time":"2021-04-02T01:29:56.139237Z"}
{"type":"l2update","product_id":"BTC-USD","changes":[["sell","59013.02","0.01453493"]],"time":"2021-04-02T01:29:56.143060Z"}
{"type":"l2update","product_id":"BTC-USD","changes":[["sell","58921.92","0.83431185"]],"time":"2021-04-02T01:29:56.143110Z"}
{"type":"l2update","product_id":"BTC-USD","changes":[["sell","58831.77","0.09129306"]],"time":"2021-04-02T01:29:56.147168Z"}
{"type":"l2update","product_id":"BTC-USD","changes":[["buy","58810.76","0.04000000"]],"time":"2021-04-02T01:29:56.150521Z"}
{"type":"l2update","product_id":"BTC-USD","changes":[["sell","58831.77","0.00000000"]],"time":"2021-04-02T01:29:56.152864Z"}
{"type":"l2update","product_id":"BTC-USD","changes":[["buy","58803.16","0.00000000"]],"time":"2021-04-02T01:29:56.154041Z"}
{"type":"l2update","product_id":"BTC-USD","changes":[["sell","59498.83","0.00000000"]],"time":"2021-04-02T01:29:56.154062Z"}
{"type":"l2update","product_id":"BTC-USD","changes":[["sell","59477.29","0.08406570"]],"time":"2021-04-02T01:29:56.161922Z"}
{"type":"l2update","product_id":"BTC-USD","changes":[["sell","59477.29","0.00000000"]],"time":"2021-04-02T01:29:56.203264Z"}
{"type":"l2update","product_id":"BTC-USD","changes":[["buy","58623.74","0.00000000"]],"time":"2021-04-02T01:29:56.205465Z"}
{"type":"l2update","product_id":"BTC-USD","changes":[["sell","58831.77","0.09129306"]],"time":"2021-04-02T01:29:56.209576Z"}
{"type":"l2update","product_id":"BTC-USD","changes":[["sell","59455.75","0.01000000"]],"time":"2021-04-02T01:29:56.213072Z"}
{"type":"l2update","product_id":"BTC-USD","changes":[["buy","58810.76","0.00000000"]],"time":"2021-04-02T01:29:56.213179Z"}
{"type":"l2update","product_id":"BTC-USD","changes":[["sell","58831.77","0.00000000"]],"time":"2021-04-02T01:29:56.214546Z"}
{"type":"l2update","product_id":"BTC-USD","changes":[["buy","58602.50","0.02635760"]],"time":"2021-04-02T01:29:56.220858Z"}
{"type":"l2update","product_id":"BTC-USD","changes":[["sell","58986.24","0.00000000"]],"time":"2021-04-02T01:29:56.221280Z"}
{"type":"l2update","product_id":"BTC-USD","changes":[["sell","58965.32","0.00847956"]],"time":"2021-04-02T01:29:56.242193Z"}
{"type":"l2update","product_id":"BTC-USD","changes":[["buy","58764.61","0.00000000"]],"time":"2021-04-02T01:29:56.252876Z"}
{"type":"l2update","product_id":"BTC-USD","changes":[["sell","58867.81","0.00000000"]],"time":"2021-04-02T01:29:56.260934Z"}
{"type":"l2update","product_id":"BTC-USD","changes":[["buy","58786.38","0.01774197"]],"time":"2021-04-02T01:29:56.268278Z"}
{"type":"l2update","product_id":"BTC-USD","changes":[["buy","58817.14","0.00000000"]],"time":"2021-04-02T01:29:56.269228Z"}
{"type":"l2update","product_id":"BTC-USD","changes":[["buy","58812.56","0.50700000"]],"time":"2021-04-02T01:29:56.269816Z"}
{"type":"l2update","product_id":"BTC-USD","changes":[["sell","58831.77","0.09129306"]],"time":"2021-04-02T01:29:56.276218Z"}
{"type":"l2update","product_id":"BTC-USD","changes":[["buy","58602.50","0.00000000"]],"time":"2021-04-02T01:29:56.321871Z"}
{"type":"l2update","product_id":"BTC-USD","changes":[["buy","57659.88","0.00000000"]],"time":"2021-04-02T01:29:56.327273Z"}
{"type":"l2update","product_id":"BTC-USD","changes":[["buy","58581.26","0.05536600"]],"time":"2021-04-02T01:29:56.333423Z"}
{"type":"l2update","product_id":"BTC-USD","changes":[["buy","57651.83","0.00382270"]],"time":"2021-04-02T01:29:56.336986Z"}
{"type":"l2update","product_id":"BTC-USD","changes":[["buy","58760.44","0.00000000"]],"time":"2021-04-02T01:29:56.339096Z"}
{"type":"l2update","product_id":"BTC-USD","changes":[["sell","58962.41","0.00000000"]],"time":"2021-04-02T01:29:56.342646Z"}
{"type":"l2update","product_id":"BTC-USD","changes":[["sell","58867.81","0.76120432"]],"time":"2021-04-02T01:29:56.344347Z"}
{"type":"l2update","product_id":"BTC-USD","changes":[["sell","58831.77","0.00000000"]],"time":"2021-04-02T01:29:56.350179Z"}
{"type":"l2update","product_id":"BTC-USD","changes":[["sell","58988.43","0.01000000"]],"time":"2021-04-02T01:29:56.351686Z"}
{"type":"l2update","product_id":"BTC-USD","changes":[["buy","58796.04","0.00000000"]],"time":"2021-04-02T01:29:56.356888Z"}
{"type":"l2update","product_id":"BTC-USD","changes":[["buy","58824.70","0.08400000"]],"time":"2021-04-02T01:29:56.363402Z"}
{"type":"l2update","product_id":"BTC-USD","changes":[["buy","58816.08","0.00000000"]],"time":"2021-04-02T01:29:56.365523Z"}
{"type":"l2update","product_id":"BTC-USD","changes":[["buy","58812.56","0.00000000"]],"time":"2021-04-02T01:29:56.365935Z"}
{"type":"l2update","product_id":"BTC-USD","changes":[["buy","58826.17","0.00000000"]],"time":"2021-04-02T01:29:56.372379Z"}
{"type":"l2update","product_id":"BTC-USD","changes":[["sell","58831.77","0.09129306"]],"time":"2021-04-02T01:29:56.374511Z"}
{"type":"l2update","product_id":"BTC-USD","changes":[["sell","58832.07","0.00000000"]],"time":"2021-04-02T01:29:56.376251Z"}
{"type":"l2update","product_id":"BTC-USD","changes":[["buy","58824.70","0.00000000"]],"time":"2021-04-02T01:29:56.378958Z"}
{"type":"l2update","product_id":"BTC-USD","changes":[["sell","58831.77","0.00000000"]],"time":"2021-04-02T01:29:56.382780Z"}
{"type":"l2update","product_id":"BTC-USD","changes":[["sell","58828.41","0.12238439"]],"time":"2021-04-02T01:29:56.386139Z"}
{"type":"l2update","product_id":"BTC-USD","changes":[["buy","58823.74","0.01560000"]],"time":"2021-04-02T01:29:56.386158Z"}
{"type":"l2update","product_id":"BTC-USD","changes":[["sell","58829.64","0.01560000"]],"time":"2021-04-02T01:29:56.397818Z"}
{"type":"l2update","product_id":"BTC-USD","changes":[["buy","58827.73","0.00000000"]],"time":"2021-04-02T01:29:56.405910Z"}
{"type":"l2update","product_id":"BTC-USD","changes":[["sell","58831.77","0.09129306"]],"time":"2021-04-02T01:29:56.431842Z"}
{"type":"l2update","product_id":"BTC-USD","changes":[["buy","58750.09","0.00000000"]],"time":"2021-04-02T01:29:56.438924Z"}
{"type":"l2update","product_id":"BTC-USD","changes":[["buy","58828.40","0.01279000"]],"time":"2021-04-02T01:29:56.449128Z"}
{"type":"l2update","product_id":"BTC-USD","changes":[["buy","58804.12","0.00000000"]],"time":"2021-04-02T01:29:56.460107Z"}
{"type":"l2update","product_id":"BTC-USD","changes":[["sell","58846.20","0.00000000"]],"time":"2021-04-02T01:29:56.463275Z"}
{"type":"l2update","product_id":"BTC-USD","changes":[["buy","58642.77","0.00000000"]],"time":"2021-04-02T01:29:56.467061Z"}
{"type":"l2update","product_id":"BTC-USD","changes":[["sell","58831.77","0.00000000"]],"time":"2021-04-02T01:29:56.471421Z"}
{"type":"l2update","product_id":"BTC-USD","changes":[["sell","58834.82","0.00000000"]],"time":"2021-04-02T01:29:56.480679Z"}
{"type":"l2update","product_id":"BTC-USD","changes":[["sell","58831.77","0.09129306"]],"time":"2021-04-02T01:29:56.486060Z"}
{"type":"l2update","product_id":"BTC-USD","changes":[["buy","58618.93","0.00852966"]],"time":"2021-04-02T01:29:56.486159Z"}
{"type":"l2update","product_id":"BTC-USD","changes":[["buy","58816.08","0.50800000"]],"time":"2021-04-02T01:29:56.486184Z"}
{"type":"l2update","product_id":"BTC-USD","changes":[["sell","58832.18","0.15763862"]],"time":"2021-04-02T01:29:56.489704Z"}
{"type":"l2update","product_id":"BTC-USD","changes":[["sell","58831.77","0.00000000"]],"time":"2021-04-02T01:29:56.490175Z"}
{"type":"l2update","product_id":"BTC-USD","changes":[["buy","58765.17","0.00887008"]],"time":"2021-04-02T01:29:56.524793Z"}
{"type":"l2update","product_id":"BTC-USD","changes":[["buy","58750.09","1.00000000"]],"time":"2021-04-02T01:29:56.524816Z"}
{"type":"l2update","product_id":"BTC-USD","changes":[["sell","59013.02","0.00000000"]],"time":"2021-04-02T01:29:56.530586Z"}
{"type":"l2update","product_id":"BTC-USD","changes":[["sell","58992.24","0.01000000"]],"time":"2021-04-02T01:29:56.541713Z"}
{"type":"l2update","product_id":"BTC-USD","changes":[["sell","58867.81","0.00000000"]],"time":"2021-04-02T01:29:56.543900Z"}
{"type":"l2update","product_id":"BTC-USD","changes":[["buy","58804.12","0.42660000"]],"time":"2021-04-02T01:29:56.549148Z"}
{"type":"l2update","product_id":"BTC-USD","changes":[["sell","58828.41","0.12075801"]],"time":"2021-04-02T01:29:56.553160Z"}
{"type":"l2update","product_id":"BTC-USD","changes":[["sell","58846.20","0.42770000"]],"time":"2021-04-02T01:29:56.557219Z"}
{"type":"l2update","product_id":"BTC-USD","changes":[["buy","58823.29","0.08400000"]],"time":"2021-04-02T01:29:56.572762Z"}
{"type":"l2update","product_id":"BTC-USD","changes":[["sell","58843.82","0.03303816"]],"time":"2021-04-02T01:29:56.576397Z"}
{"type":"l2update","product_id":"BTC-USD","changes":[["sell","58831.77","0.09129306"]],"time":"2021-04-02T01:29:56.576435Z"}
{"type":"l2update","product_id":"BTC-USD","changes":[["buy","58796.67","0.13305452"]],"time":"2021-04-02T01:29:56.604073Z"}
{"type":"l2update","product_id":"BTC-USD","changes":[["buy","58762.18","0.03548020"]],"time":"2021-04-02T01:29:56.608274Z"}
{"type":"l2update","product_id":"BTC-USD","changes":[["sell","58867.81","0.16620432"]],"time":"2021-04-02T01:29:56.628221Z"}
{"type":"l2update","product_id":"BTC-USD","changes":[["buy","57500.00","32.28931245"]],"time":"2021-04-02T01:29:56.668491Z"}
{"type":"l2update","product_id":"BTC-USD","changes":[["sell","58831.77","0.00000000"]],"time":"2021-04-02T01:29:56.668982Z"}
{"type":"l2update","product_id":"BTC-USD","changes":[["buy","58760.57","0.00000000"]],"time":"2021-04-02T01:29:56.671344Z"}
{"type":"l2update","product_id":"BTC-USD","changes":[["sell","58831.77","0.09129306"]],"time":"2021-04-02T01:29:56.686926Z"}
{"type":"l2update","product_id":"BTC-USD","changes":[["sell","58831.77","0.00000000"]],"time":"2021-04-02T01:29:56.692158Z"}